Workbook

Sheet Income Statement
A1: ACME Corporation (ACME) — Income Statement
A2: Units: USD millions · only the source tabs hold hardcoded data
A3: Sample data — fictional company for demonstration
A6: Line Item | B6: 45291 | C6: 45657 | D6: 46022
A7: Revenues | B7: 1000 | C7: 1150 | D7: 1322
A8: Cost of revenues | B8: -400 | C8: -460 | D8: -529
A9: Gross profit | B9: =B7+B8 | C9: =C7+C8 | D9: =D7+D8
A10: Research and development | B10: -150 | C10: -172 | D10: -198
A11: Selling, general and administrative | B11: -200 | C11: -230 | D11: -264
A12: Income from operations | B12: =B9+B10+B11 | C12: =C9+C10+C11 | D12: =D9+D10+D11
A13: Interest expense | B13: -10 | C13: -10 | D13: -10
A14: Interest income | B14: 5 | C14: 5 | D14: 5
A15: Income before income taxes | B15: =B12+B13+B14 | C15: =C12+C13+C14 | D15: =D12+D13+D14
A16: Provision for income taxes | B16: -51 | C16: -59 | D16: -68
A17: Net income | B17: =B15+B16 | C17: =C15+C16 | D17: =D15+D16

Sheet Balance Sheet
A1: ACME Corporation (ACME) — Balance Sheet
A2: Units: USD millions
A3: Sample data — fictional company for demonstration
A6: Line Item | B6: 45291 | C6: 45657 | D6: 46022
A7: ASSETS
A8: Cash and cash equivalents | B8: 100 | C8: 130 | D8: 168
A9: Short-term investments | B9: 50 | C9: 55 | D9: 60
A10: Accounts receivable, net | B10: 120 | C10: 138 | D10: 159
A11: Inventory | B11: 80 | C11: 92 | D11: 106
A12: Property and equipment, net | B12: 400 | C12: 460 | D12: 529
A13: Goodwill | B13: 60 | C13: 60 | D13: 60
A14: Other non-current assets | B14: 30 | C14: 33 | D14: 36
A15: Total assets | B15: =SUM(B8:B14) | C15: =SUM(C8:C14) | D15: =SUM(D8:D14)
A17: LIABILITIES
A18: Accounts payable | B18: 70 | C18: 80 | D18: 92
A19: Accrued compensation | B19: 40 | C19: 46 | D19: 53
A20: Deferred revenue | B20: 30 | C20: 35 | D20: 40
A21: Short-term debt | B21: 20 | C21: 20 | D21: 20
A22: Long-term debt | B22: 200 | C22: 210 | D22: 220
A23: Operating lease liabilities | B23: 40 | C23: 44 | D23: 48
A24: Other non-current liabilities | B24: 25 | C24: 28 | D24: 31
A25: Total liabilities | B25: =SUM(B18:B24) | C25: =SUM(C18:C24) | D25: =SUM(D18:D24)
A27: STOCKHOLDERS' EQUITY
A28: Common stock and paid-in capital | B28: 150 | C28: 150 | D28: 150
A29: Retained earnings | B29: 265 | C29: 355 | D29: 464
A30: Total stockholders' equity | B30: =SUM(B28:B29) | C30: =SUM(C28:C29) | D30: =SUM(D28:D29)

Sheet Cash Flow
A1: ACME Corporation (ACME) — Cash Flow Statement
A2: Units: USD millions · FY2023 omitted (no prior-year balance in sample)
A3: Sample data — fictional company for demonstration
A6: Line Item | B6: 45657 | C6: 46022
A7: Net income | B7: 224 | C7: 258
A8: Depreciation & amortization | B8: 70 | C8: 80
A9: Working capital & other | B9: -2 | C9: -4
A10: Cash from operations | B10: 292 | C10: 334
A11: Capital expenditures | B11: -130 | C11: -149
A12: Investments & other | B12: -8 | C12: -8
A13: Cash from investing | B13: -138 | C13: -157
A14: Debt issued, net | B14: 10 | C14: 10
A15: Dividends paid | B15: -134 | C15: -149
A16: Cash from financing | B16: -124 | C16: -139
A17: Net change in cash | B17: 30 | C17: 38

Sheet Condensed Financials
A1: ACME Corporation (ACME) — Condensed Financials
A2: All aggregates are SUMIFs over the CLASSIFICATION TABLE below — toggle column E to reclassify
A3: Sample data — fictional company for demonstration
A5: Line Item | B5: 45291 | C5: 45657 | D5: 46022
A7: A. CONDENSED INCOME STATEMENT
A8: Net income | B8: ='Income Statement'!B17 | C8: ='Income Statement'!C17 | D8: ='Income Statement'!D17
A9: Interest expense (abs) | B9: =ABS('Income Statement'!B13) | C9: =ABS('Income Statement'!C13) | D9: =ABS('Income Statement'!D13)
A10: Interest income | B10: ='Income Statement'!B14 | C10: ='Income Statement'!C14 | D10: ='Income Statement'!D14
A11: Net interest expense | B11: =B9-B10 | C11: =C9-C10 | D11: =D9-D10
A12: Effective tax rate | B12: =IFERROR(ABS('Income Statement'!B16)/'Income Statement'!B15,0) | C12: =IFERROR(ABS('Income Statement'!C16)/'Income Statement'!C15,0) | D12: =IFERROR(ABS('Income Statement'!D16)/'Income Statement'!D15,0)
A13: Net interest after tax | B13: =B11*(1-B12) | C13: =C11*(1-C12) | D13: =D11*(1-D12)
A14: NOPAT | B14: =B8+B13 | C14: =C8+C13 | D14: =D8+D13
A16: B. CONDENSED BALANCE SHEET
A17: Operating Working Capital Assets | B17: =SUMIF($E$33:$E$48,"Operating Working Capital Asset",B$33:B$48) | C17: =SUMIF($E$33:$E$48,"Operating Working Capital Asset",C$33:C$48) | D17: =SUMIF($E$33:$E$48,"Operating Working Capital Asset",D$33:D$48)
A18: Operating Working Capital Liabilities | B18: =SUMIF($E$33:$E$48,"Operating Working Capital Liability",B$33:B$48) | C18: =SUMIF($E$33:$E$48,"Operating Working Capital Liability",C$33:C$48) | D18: =SUMIF($E$33:$E$48,"Operating Working Capital Liability",D$33:D$48)
A19: NET OPERATING WORKING CAPITAL (NOWC) | B19: =B17-B18 | C19: =C17-C18 | D19: =D17-D18
A21: Operating Long-Term Assets | B21: =SUMIF($E$33:$E$48,"Operating Long-Term Asset",B$33:B$48) | C21: =SUMIF($E$33:$E$48,"Operating Long-Term Asset",C$33:C$48) | D21: =SUMIF($E$33:$E$48,"Operating Long-Term Asset",D$33:D$48)
A22: Operating Long-Term Liabilities | B22: =SUMIF($E$33:$E$48,"Operating Long-Term Liability",B$33:B$48) | C22: =SUMIF($E$33:$E$48,"Operating Long-Term Liability",C$33:C$48) | D22: =SUMIF($E$33:$E$48,"Operating Long-Term Liability",D$33:D$48)
A23: NET OPERATING LT ASSETS (NOLA) | B23: =B21-B22 | C23: =C21-C22 | D23: =D21-D22
A25: NET OPERATING ASSETS (NOA) | B25: =B19+B23 | C25: =C19+C23 | D25: =D19+D23
A27: Financial Assets | B27: =SUMIF($E$33:$E$48,"Financial Asset",B$33:B$48) | C27: =SUMIF($E$33:$E$48,"Financial Asset",C$33:C$48) | D27: =SUMIF($E$33:$E$48,"Financial Asset",D$33:D$48)
A28: Financial Liabilities | B28: =SUMIF($E$33:$E$48,"Financial Liability",B$33:B$48) | C28: =SUMIF($E$33:$E$48,"Financial Liability",C$33:C$48) | D28: =SUMIF($E$33:$E$48,"Financial Liability",D$33:D$48)
A29: NET DEBT | B29: =B28-B27 | C29: =C28-C27 | D29: =D28-D27
A30: EQUITY (NOA − Net Debt) | B30: =B25-B29 | C30: =C25-C29 | D30: =D25-D29
A31: Reported equity | B31: ='Balance Sheet'!B30 | C31: ='Balance Sheet'!C30 | D31: ='Balance Sheet'!D30
A32: C. CLASSIFICATION TABLE — click any cell in column E for the dropdown
A33: Cash and cash equivalents | B33: ='Balance Sheet'!B8 | C33: ='Balance Sheet'!C8 | D33: ='Balance Sheet'!D8 | E33: Financial Asset
A34: Short-term investments | B34: ='Balance Sheet'!B9 | C34: ='Balance Sheet'!C9 | D34: ='Balance Sheet'!D9 | E34: Financial Asset
A35: Accounts receivable, net | B35: ='Balance Sheet'!B10 | C35: ='Balance Sheet'!C10 | D35: ='Balance Sheet'!D10 | E35: Operating Working Capital Asset
A36: Inventory | B36: ='Balance Sheet'!B11 | C36: ='Balance Sheet'!C11 | D36: ='Balance Sheet'!D11 | E36: Operating Working Capital Asset
A37: Property and equipment, net | B37: ='Balance Sheet'!B12 | C37: ='Balance Sheet'!C12 | D37: ='Balance Sheet'!D12 | E37: Operating Long-Term Asset
A38: Goodwill | B38: ='Balance Sheet'!B13 | C38: ='Balance Sheet'!C13 | D38: ='Balance Sheet'!D13 | E38: Operating Long-Term Asset
A39: Other non-current assets | B39: ='Balance Sheet'!B14 | C39: ='Balance Sheet'!C14 | D39: ='Balance Sheet'!D14 | E39: Operating Long-Term Asset
A40: Accounts payable | B40: ='Balance Sheet'!B18 | C40: ='Balance Sheet'!C18 | D40: ='Balance Sheet'!D18 | E40: Operating Working Capital Liability
A41: Accrued compensation | B41: ='Balance Sheet'!B19 | C41: ='Balance Sheet'!C19 | D41: ='Balance Sheet'!D19 | E41: Operating Working Capital Liability
A42: Deferred revenue | B42: ='Balance Sheet'!B20 | C42: ='Balance Sheet'!C20 | D42: ='Balance Sheet'!D20 | E42: Operating Working Capital Liability
A43: Short-term debt | B43: ='Balance Sheet'!B21 | C43: ='Balance Sheet'!C21 | D43: ='Balance Sheet'!D21 | E43: Financial Liability
A44: Long-term debt | B44: ='Balance Sheet'!B22 | C44: ='Balance Sheet'!C22 | D44: ='Balance Sheet'!D22 | E44: Financial Liability
A45: Operating lease liabilities | B45: ='Balance Sheet'!B23 | C45: ='Balance Sheet'!C23 | D45: ='Balance Sheet'!D23 | E45: Operating Long-Term Liability
A46: Other non-current liabilities | B46: ='Balance Sheet'!B24 | C46: ='Balance Sheet'!C24 | D46: ='Balance Sheet'!D24 | E46: Operating Long-Term Liability
...

Sheet ALT DuPont
A1: ACME Corporation (ACME) — ALT DuPont
A2: ROE = RNOA + FLEV × Spread · all inputs formula-linked to Condensed Financials
A3: Sample data — fictional company for demonstration
A5: Line Item | B5: 45291 | C5: 45657 | D5: 46022
A7: NOPAT margin | B7: =IFERROR('Condensed Financials'!B14/'Income Statement'!B7,0) | C7: =IFERROR('Condensed Financials'!C14/'Income Statement'!C7,0) | D7: =IFERROR('Condensed Financials'!D14/'Income Statement'!D7,0)
A8: Avg NOA | B8: n/a | C8: =('Condensed Financials'!C25+'Condensed Financials'!B25)/2 | D8: =('Condensed Financials'!D25+'Condensed Financials'!C25)/2
A9: Asset turnover | B9: n/a | C9: =IFERROR('Income Statement'!C7/C8,0) | D9: =IFERROR('Income Statement'!D7/D8,0)
A10: RNOA | B10: n/a | C10: =C7*C9 | D10: =D7*D9
A11: Avg net debt | B11: n/a | C11: =('Condensed Financials'!C29+'Condensed Financials'!B29)/2 | D11: =('Condensed Financials'!D29+'Condensed Financials'!C29)/2
A12: After-tax cost of debt | B12: n/a | C12: =IFERROR('Condensed Financials'!C13/C11,0) | D12: =IFERROR('Condensed Financials'!D13/D11,0)
A13: Spread | B13: n/a | C13: =C10-C12 | D13: =D10-D12
A14: Avg equity | B14: n/a | C14: =('Condensed Financials'!C30+'Condensed Financials'!B30)/2 | D14: =('Condensed Financials'!D30+'Condensed Financials'!C30)/2
A15: FLEV | B15: n/a | C15: =IFERROR(C11/C14,0) | D15: =IFERROR(D11/D14,0)
A16: ROE (RNOA + FLEV×Spread) | B16: n/a | C16: =C10+C13*C15 | D16: =D10+D13*D15
A17: Actual ROE (NI / Avg equity) | B17: n/a | C17: =IFERROR('Condensed Financials'!C8/C14,0) | D17: =IFERROR('Condensed Financials'!D8/D14,0)

Sheet Model_Base
A1: ACME Corporation (ACME) — Residual Income Model — BASE
A2: 10-year forecast · blue cells are editable inputs
A3: Sample data — fictional company for demonstration
A4: Beta | B4: 1.1
A5: Equity risk premium | B5: 0.05
A6: Risk-free rate | B6: 0.04
A7: Cost of equity (Ke) | B7: =B6+B4*B5
A9: Year | B9: 2025 | C9: 2026 | D9: 2027 | E9: 2028 | F9: 2029 | G9: 2030 | H9: 2031 | I9: 2032 | J9: 2033 | K9: 2034 | L9: 2035
A10: Revenue growth | C10: 0.12 | D10: 0.11 | E10: 0.1 | F10: 0.09 | G10: 0.08 | H10: 0.07 | I10: 0.06 | J10: 0.05 | K10: 0.045 | L10: 0.04
A11: NOPAT margin | C11: 0.2 | D11: 0.195 | E11: 0.19 | F11: 0.18 | G11: 0.17 | H11: 0.16 | I11: 0.155 | J11: 0.15 | K11: 0.145 | L11: 0.14
A12: NOWC / sales | C12: =C16/C15 | D12: 0.06 | E12: 0.06 | F12: 0.06 | G12: 0.06 | H12: 0.06 | I12: 0.06 | J12: 0.06 | K12: 0.06 | L12: 0.06
A13: NOLA / sales | C13: =C17/C15 | D13: 0.44 | E13: 0.46 | F13: 0.48 | G13: 0.5 | H13: 0.52 | I13: 0.54 | J13: 0.56 | K13: 0.58 | L13: 0.6
A15: Sales | B15: ='Income Statement'!D7 | C15: =B15*(1+C10) | D15: =C15*(1+D10) | E15: =D15*(1+E10) | F15: =E15*(1+F10) | G15: =F15*(1+G10) | H15: =G15*(1+H10) | I15: =H15*(1+I10) | J15: =I15*(1+J10) | ... L15: =K15*(1+L10)
A16: NOWC (beg) | C16: ='Condensed Financials'!D19 | D16: =D12*D15 | E16: =E12*E15 | F16: =F12*F15 | G16: =G12*G15 | H16: =H12*H15 | I16: =I12*I15 | J16: =J12*J15 | K16: =K12*K15 | L16: =L12*L15
A17: NOLA (beg) | C17: ='Condensed Financials'!D23 | D17: =D13*D15 | E17: =E13*E15 | F17: =F13*F15 | G17: =G13*G15 | H17: =H13*H15 | I17: =I13*I15 | J17: =J13*J15 | K17: =K13*K15 | L17: =L13*L15
A18: Net debt (beg) | C18: ='Condensed Financials'!D29 | D18: =$C$18/($C$16+$C$17)*(D16+D17) | E18: =$C$18/($C$16+$C$17)*(E16+E17) | F18: =$C$18/($C$16+$C$17)*(F16+F17) | G18: =$C$18/($C$16+$C$17)*(G16+G17) | H18: =$C$18/($C$16+$C$17)*(H16+H17) | I18: =$C$18/($C$16+$C$17)*(I16+I17) | J18: =$C$18/($C$16+$C$17)*(J16+J17) | K18: =$C$18/($C$16+$C$17)*(K16+K17) | L18: =$C$18/($C$16+$C$17)*(L16+L17)
A19: Equity (beg) | C19: =C16+C17-C18 | D19: =D16+D17-D18 | E19: =E16+E17-E18 | F19: =F16+F17-F18 | G19: =G16+G17-G18 | H19: =H16+H17-H18 | I19: =I16+I17-I18 | J19: =J16+J17-J18 | ... L19: =L16+L17-L18
A21: NOPAT | C21: =C15*C11 | D21: =D15*D11 | E21: =E15*E11 | F21: =F15*F11 | G21: =G15*G11 | H21: =H15*H11 | I21: =I15*I11 | J21: =J15*J11 | ... L21: =L15*L11
A22: Net income | C22: =C21-C18*0.03 | D22: =D21-D18*0.03 | E22: =E21-E18*0.03 | F22: =F21-F18*0.03 | G22: =G21-G18*0.03 | H22: =H21-H18*0.03 | I22: =I21-I18*0.03 | J22: =J21-J18*0.03 | ... L22: =L21-L18*0.03
A23: Abnormal earnings | C23: =C22-C19*$B$7 | D23: =D22-D19*$B$7 | E23: =E22-E19*$B$7 | F23: =F22-F19*$B$7 | G23: =G22-G19*$B$7 | H23: =H22-H19*$B$7 | I23: =I22-I19*$B$7 | J23: =J22-J19*$B$7 | ... L23: =L22-L19*$B$7
A24: PV factor | C24: =1/(1+$B$7) | D24: =C24/(1+$B$7) | E24: =D24/(1+$B$7) | F24: =E24/(1+$B$7) | G24: =F24/(1+$B$7) | H24: =G24/(1+$B$7) | I24: =H24/(1+$B$7) | J24: =I24/(1+$B$7) | K24: =J24/(1+$B$7) | L24: =K24/(1+$B$7)
A25: PV of AE | C25: =C23*C24 | D25: =D23*D24 | E25: =E23*E24 | F25: =F23*F24 | G25: =G23*G24 | H25: =H23*H24 | I25: =I23*I24 | J25: =J23*J24 | ... L25: =L23*L24
A27: Sum PV(AE) | C27: =SUM(C25:L25)
A28: Terminal value (g=3%) | C28: =L23*(1+0.03)/($B$7-0.03)*L24
A29: Beginning book equity | C29: =C19
A30: Intrinsic value of equity | C30: =C27+C28+C29
A31: Diluted shares (M) | C31: 100
A32: INTRINSIC VALUE PER SHARE | C32: =C30/C31
A34: Note: real builds carry Model_Bear / Model_Base / Model_Bull plus a Scenario_Summary with probability weighting — this sample shows one scenario.
