Workbook

Sheet Income Statement
A1: Company: Alphabet Inc. (GOOGL)
A2: Statement: Consolidated Statements of Income
A3: Units: USD in Millions
A4: Source: SEC 10-K filings, as filed (acc. 0001652044-26-000018 / 0001652044-24-000022 / 0001652044-22-000019 / 0001652044-20-000008 / 0001652044-18-000007; each year from the newest filing covering it)
A5: DEMO WORKBOOK: financial data as filed with the SEC (real); model inputs ILLUSTRATIVE ONLY — not analysis, not advice.
A6: Line Item | B6: 42735 | C6: 43100 | D6: 43465 | E6: 43830 | F6: 44196 | G6: 44561 | H6: 44926 | I6: 45291 | J6: 45657 | K6: 46022
A7: Revenues | B7: 90272 | C7: 110855 | D7: 136819 | E7: 161857 | F7: 182527 | G7: 257637 | H7: 282836 | I7: 307394 | J7: 350018 | K7: 402836
A8: Cost of revenues | B8: -35138 | C8: -45583 | D8: -59549 | E8: -71896 | F8: -84732 | G8: -110939 | H8: -126203 | I8: -133332 | J8: -146306 | K8: -162535
A9: Gross profit | B9: =B7+B8 | C9: =C7+C8 | D9: =D7+D8 | E9: =E7+E8 | F9: =F7+F8 | G9: =G7+G8 | H9: =H7+H8 | I9: =I7+I8 | ... K9: =K7+K8
A10: Research and development | B10: -13948 | C10: -16625 | D10: -21419 | E10: -26018 | F10: -27573 | G10: -31562 | H10: -39500 | I10: -45427 | J10: -49326 | K10: -61087
A11: Sales and marketing | B11: -10485 | C11: -12893 | D11: -16333 | E11: -18464 | F11: -17946 | G11: -22912 | H11: -26567 | I11: -27917 | J11: -27808 | K11: -28693
A12: General and administrative | B12: -6985 | C12: -6840 | D12: -6923 | E12: -9551 | F12: -11052 | G12: -13510 | H12: -15724 | I12: -16425 | J12: -14188 | K12: -21482
A13: European Commission fines | B13: 0 | C13: -2736 | D13: -5071 | E13: -1697 | F13: 0
A14: Total costs and expenses | B14: -66556 | C14: -84677 | D14: -109295 | E14: -127626 | F14: -141303 | G14: -178923 | H14: -207994 | I14: -223101 | J14: -237628 | K14: -273797
A15: Income from operations | B15: 23716 | C15: 26178 | D15: 27524 | E15: 34231 | F15: 41224 | G15: 78714 | H15: 74842 | I15: 84293 | J15: 112390 | K15: 129039
A16: Other income (expense), net | B16: 434 | C16: 1015 | D16: 7389 | E16: 5394 | F16: 6858 | G16: 12020 | H16: -3514 | I16: 1424 | J16: 7425 | K16: 29787
A17: Income before income taxes | B17: 24150 | C17: 27193 | D17: 34913 | E17: 39625 | F17: 48082 | G17: 90734 | H17: 71328 | I17: 85717 | J17: 119815 | K17: 158826
A18: Provision for income taxes | B18: -4672 | C18: -14531 | D18: -4177 | E18: -5282 | F18: -7813 | G18: -14701 | H18: -11356 | I18: -11922 | J18: -19697 | K18: -26656
A19: Net income | B19: 19478 | C19: 12662 | D19: 30736 | E19: 34343 | F19: 40269 | G19: 76033 | H19: 59972 | I19: 73795 | J19: 100118 | K19: 132170
A21: Basic earnings per share | B21: 28.32 | C21: 18.27 | D21: 44.22 | E21: 49.59 | F21: 2.96 | G21: 5.69 | H21: 4.59 | I21: 5.84 | J21: 8.13 | K21: 10.91
A22: Diluted earnings per share | B22: 27.85 | C22: 18 | D22: 43.7 | E22: 49.16 | F22: 2.93 | G22: 5.61 | H22: 4.56 | I22: 5.8 | J22: 8.04 | K22: 10.81
A23: Basic shares outstanding (M, wtd avg) | H23: 13063 | I23: 12630 | J23: 12319 | K23: 12116
A24: Diluted shares outstanding (M, wtd avg) | H24: 13159 | I24: 12722 | J24: 12447 | K24: 12230
A26: Note: EPS and weighted-average shares as filed (newest filing wins): FY2016-FY2019 pre 20-for-1 split (Jul 2022); FY2020 onward split-adjusted. Pre-2022 share counts were class-dimensioned in XBRL and are omitted.
A28: QUARTERLY (AS-FILED 10-Q; Q4 DERIVED)
A29: As-filed 10-Q discrete quarters (annual sign conventions: expenses negative). Q4 derived: IS/CF = annual FY column − Σ(Q1–Q3); BS = fiscal year-end (10-K). EPS/share rows non-additive (no Q4).
B31: Q1 2024 | C31: Q2 2024 | D31: Q3 2024 | E31: Q4 2024 | F31: Q1 2025 | G31: Q2 2025 | H31: Q3 2025 | I31: Q4 2025 | J31: Q1 2026
A32: Line Item | B32: 45382 | C32: 45473 | D32: 45565 | E32: 45657 | F32: 45747 | G32: 45838 | H32: 45930 | I32: 46022 | J32: 46112
A34: Revenues | B34: 80539 | C34: 84742 | D34: 88268 | E34: 96469 | F34: 90234 | G34: 96428 | H34: 102346 | I34: 113828 | J34: 109896
A35: Cost of revenues | B35: -33712 | C35: -35507 | D35: -36474 | E35: -40613 | F35: -36361 | G35: -39039 | H35: -41369 | I35: -45766 | J35: -41271
A36: Gross profit | B36: =B34+B35 | C36: =C34+C35 | D36: =D34+D35 | E36: =E34+E35 | F36: =F34+F35 | G36: =G34+G35 | H36: =H34+H35 | I36: =I34+I35 | J36: =J34+J35
A37: Research and development | B37: -11903 | C37: -11860 | D37: -12447 | E37: -13116 | F37: -13556 | G37: -13808 | H37: -15151 | I37: -18572 | J37: -17032
A38: Sales and marketing | B38: -6426 | C38: -6792 | D38: -7227 | E38: -7363 | F38: -6172 | G38: -7101 | H38: -7205 | I38: -8215 | J38: -7606
A39: General and administrative | B39: -3026 | C39: -3158 | D39: -3599 | E39: -4405 | F39: -3539 | G39: -5209 | H39: -7393 | I39: -5341 | J39: -4291
A40: European Commission fines
A41: Total costs and expenses | B41: -55067 | C41: -57317 | D41: -59747 | E41: -65497 | F41: -59628 | G41: -65157 | H41: -71118 | I41: -77894 | J41: -70200
A42: Income from operations | B42: 25472 | C42: 27425 | D42: 28521 | E42: 30972 | F42: 30606 | G42: 31271 | H42: 31228 | I42: 35934 | J42: 39696
A43: Other income (expense), net | B43: 2843 | C43: 126 | D43: 3185 | E43: 1271 | F43: 11183 | G43: 2662 | H43: 12759 | I43: 3183 | J43: 37716
A44: Income before income taxes | B44: 28315 | C44: 27551 | D44: 31706 | E44: 32243 | F44: 41789 | G44: 33933 | H44: 43987 | I44: 39117 | J44: 77412
A45: Provision for income taxes | B45: -4653 | C45: -3932 | D45: -5405 | E45: -5707 | F45: -7249 | G45: -5737 | H45: -9008 | I45: -4662 | J45: -14834
...

Sheet Balance Sheet
A1: Company: Alphabet Inc. (GOOGL)
A2: Statement: Consolidated Balance Sheets
A3: Units: USD in Millions
A4: Source: SEC 10-K filings, as filed (acc. 0001652044-26-000018 / 0001652044-24-000022 / 0001652044-22-000019 / 0001652044-20-000008 / 0001652044-18-000007; each year from the newest filing covering it)
A6: Line Item | B6: 42735 | C6: 43100 | D6: 43465 | E6: 43830 | F6: 44196 | G6: 44561 | H6: 44926 | I6: 45291 | J6: 45657 | K6: 46022
A7: CURRENT ASSETS
A8: Cash and cash equivalents | B8: 12918 | C8: 10715 | D8: 16701 | E8: 18498 | F8: 26465 | G8: 20945 | H8: 21879 | I8: 24048 | J8: 23466 | K8: 30708
A9: Marketable securities | B9: 73415 | C9: 91156 | D9: 92439 | E9: 101177 | F9: 110229 | G9: 118704 | H9: 91883 | I9: 86868 | J9: 72191 | K9: 96135
A10: Accounts receivable, net | B10: 14137 | C10: 18336 | D10: 20838 | E10: 25326 | F10: 30930 | G10: 39304 | H10: 40258 | I10: 47964 | J10: 52340 | K10: 62886
A11: Income taxes receivable, net | B11: 95 | C11: 369 | D11: 355 | E11: 2166 | F11: 454 | G11: 966
A12: Inventory | B12: 268 | C12: 749 | D12: 1107 | E12: 999 | F12: 728 | G12: 1170
A13: Other current assets | B13: 4575 | C13: 2983 | D13: 4236 | E13: 4412 | F13: 5490 | G13: 7054 | H13: 10775 | I13: 12650 | J13: 15714 | K13: 16309
A14: Total current assets | B14: =SUM(B8:B13) | C14: =SUM(C8:C13) | D14: =SUM(D8:D13) | E14: =SUM(E8:E13) | F14: =SUM(F8:F13) | G14: =SUM(G8:G13) | H14: =SUM(H8:H13) | I14: =SUM(I8:I13) | ... K14: =SUM(K8:K13)
A16: NON-CURRENT ASSETS
A17: Non-marketable securities | B17: 5878 | C17: 7813 | D17: 13859 | E17: 13078 | F17: 20703 | G17: 29549 | H17: 30492 | I17: 31008 | J17: 37982 | K17: 68687
A18: Deferred income taxes | B18: 383 | C18: 680 | D18: 737 | E18: 721 | F18: 1084 | G18: 1284 | H18: 5261 | I18: 12169 | J18: 17180 | K18: 9113
A19: Property and equipment, net | B19: 34234 | C19: 42383 | D19: 59719 | E19: 73646 | F19: 84749 | G19: 97599 | H19: 112668 | I19: 134345 | J19: 171036 | K19: 246597
A20: Operating lease assets | E20: 10941 | F20: 12211 | G20: 12959 | H20: 14381 | I20: 14091 | J20: 13588 | K20: 15221
A21: Goodwill | B21: 16468 | C21: 16747 | D21: 17888 | E21: 20624 | F21: 21175 | G21: 22956 | H21: 28960 | I21: 29198 | J21: 31885 | K21: 33380
A22: Intangible assets, net | B22: 3307 | C22: 2692 | D22: 2220 | E22: 1979 | F22: 1445 | G22: 1417
A23: Other non-current assets | B23: 1819 | C23: 2672 | D23: 2693 | E23: 2342 | F23: 3953 | G23: 5361 | H23: 8707 | I23: 10051 | J23: 14874 | K23: 16245
A24: Total assets | B24: =B14+SUM(B17:B23) | C24: =C14+SUM(C17:C23) | D24: =D14+SUM(D17:D23) | E24: =E14+SUM(E17:E23) | F24: =F14+SUM(F17:F23) | G24: =G14+SUM(G17:G23) | H24: =H14+SUM(H17:H23) | I24: =I14+SUM(I17:I23) | ... K24: =K14+SUM(K17:K23)
A26: CURRENT LIABILITIES
A27: Accounts payable | B27: 2041 | C27: 3137 | D27: 4378 | E27: 5561 | F27: 5589 | G27: 6037 | H27: 5128 | I27: 7493 | J27: 7987 | K27: 12200
A28: Accrued compensation and benefits | B28: 3976 | C28: 4581 | D28: 6839 | E28: 8495 | F28: 11086 | G28: 13889 | H28: 14028 | I28: 15140 | J28: 15069 | K28: 17546
A29: Accrued expenses and other current liabilities | B29: 6144 | C29: 10177 | D29: 16958 | E29: 23067 | F29: 28631 | G29: 31236 | H29: 37866 | I29: 46168 | J29: 51228 | K29: 55557
A30: Accrued revenue share | B30: 2942 | C30: 3975 | D30: 4592 | E30: 5916 | F30: 7500 | G30: 8996 | H30: 8370 | I30: 8876 | J30: 9802 | K30: 10864
A31: Deferred revenue | B31: 1099 | C31: 1432 | D31: 1784 | E31: 1908 | F31: 2543 | G31: 3288 | H31: 3908 | I31: 4137 | J31: 5036 | K31: 6578
A32: Income taxes payable, net | B32: 554 | C32: 881 | D32: 69 | E32: 274 | F32: 1485 | G32: 808
A33: Total current liabilities | B33: =SUM(B27:B32) | C33: =SUM(C27:C32) | D33: =SUM(D27:D32) | E33: =SUM(E27:E32) | F33: =SUM(F27:F32) | G33: =SUM(G27:G32) | H33: =SUM(H27:H32) | I33: =SUM(I27:I32) | ... K33: =SUM(K27:K32)
A35: NON-CURRENT LIABILITIES
A36: Long-term debt | B36: 3935 | C36: 3969 | D36: 4012 | E36: 4554 | F36: 13932 | G36: 14817 | H36: 14701 | I36: 13253 | J36: 10883 | K36: 46547
A37: Deferred revenue, non-current | B37: 202 | C37: 340 | D37: 396 | E37: 358 | F37: 481 | G37: 535 | H37: 599 | I37: 911
A38: Income taxes payable, non-current | B38: 4677 | C38: 12812 | D38: 11327 | E38: 9885 | F38: 8849 | G38: 9176 | H38: 9258 | I38: 8474 | J38: 8782 | K38: 9531
A39: Deferred income taxes, non-current | B39: 226 | C39: 430 | D39: 1264 | E39: 1701 | F39: 3561 | G39: 5257 | H39: 514 | I39: 485
A40: Operating lease liabilities, non-current | E40: 10214 | F40: 11146 | G40: 11389 | H40: 12501 | I40: 12460 | J40: 11691 | K40: 12744
A41: Other long-term liabilities | B41: 2665 | C41: 3059 | D41: 3545 | E41: 2534 | F41: 2269 | G41: 2205 | H41: 2247 | I41: 1616 | J41: 4694 | K41: 8449
A42: Total liabilities | B42: =B33+SUM(B36:B41) | C42: =C33+SUM(C36:C41) | D42: =D33+SUM(D36:D41) | E42: =E33+SUM(E36:E41) | F42: =F33+SUM(F36:F41) | G42: =G33+SUM(G36:G41) | H42: =H33+SUM(H36:H41) | I42: =I33+SUM(I36:I41) | ... K42: =K33+SUM(K36:K41)
A44: STOCKHOLDERS' EQUITY
A45: Class A/B/C stock and additional paid-in capital | B45: 36307 | C45: 40247 | D45: 45049 | E45: 50552 | F45: 58510 | G45: 61774 | H45: 68184 | I45: 76534 | J45: 84800 | K45: 93126
...

Sheet Cash Flow Statement
A1: Company: Alphabet Inc. (GOOGL)
A2: Statement: Consolidated Statements of Cash Flows
A3: Units: USD in Millions
A4: Source: SEC 10-K filings, as filed (acc. 0001652044-26-000018 / 0001652044-24-000022 / 0001652044-22-000019 / 0001652044-20-000008 / 0001652044-18-000007; each year from the newest filing covering it)
A6: Line Item | B6: 42735 | C6: 43100 | D6: 43465 | E6: 43830 | F6: 44196 | G6: 44561 | H6: 44926 | I6: 45291 | J6: 45657 | K6: 46022
A7: OPERATING ACTIVITIES
A8: Net income | B8: 19478 | C8: 12662 | D8: 30736 | E8: 34343 | F8: 40269 | G8: 76033 | H8: 59972 | I8: 73795 | J8: 100118 | K8: 132170
A9: Adjustments:
A10: Depreciation and impairment of property and equipment | B10: 5267 | C10: 6103 | D10: 8164 | E10: 10856 | F10: 12905
A11: Depreciation of property and equipment | G11: 10273 | H11: 13475 | I11: 11946 | J11: 15311 | K11: 21136
A12: Amortization and impairment of intangible assets | B12: 877 | C12: 812 | D12: 871 | E12: 925 | F12: 792
A13: Stock-based compensation expense | B13: 6703 | C13: 7679 | D13: 9353 | E13: 10794 | F13: 12991 | G13: 15376 | H13: 19362 | I13: 22460 | J13: 22785 | K13: 24953
A14: Deferred income taxes | B14: -38 | C14: 258 | D14: 778 | E14: 173 | F14: 1390 | G14: 1808 | H14: -8081 | I14: -7763 | J14: -5257 | K14: 8348
A15: Loss on marketable and non-marketable investments, net | B15: 275
A16: (Gain) loss on debt and equity securities, net | C16: 37 | D16: -6650 | E16: -2798 | F16: -6317 | G16: -12270 | H16: 5519 | I16: 823 | J16: -2671 | K16: -24620
A17: Other | B17: 174 | C17: 294 | D17: -189 | E17: -592 | F17: 1267 | G17: 1955 | H17: 3483 | I17: 4330 | J17: 3419 | K17: 2108
A18: Changes in assets and liabilities, net of effects of acquisitions:
A19: Accounts receivable, net | B19: -2578 | C19: -3768 | D19: -2169 | E19: -4340 | F19: -6524 | G19: -9095 | H19: -2317 | I19: -7833 | J19: -5891 | K19: -8779
A20: Income taxes, net | B20: 3125 | C20: 8211 | D20: -2251 | E20: -3128 | F20: 1209 | G20: -625 | H20: 584 | I20: 523 | J20: -2418 | K20: -3226
A21: Other assets | B21: 312 | C21: -2164 | D21: -1207 | E21: -621 | F21: -1330 | G21: -1846 | H21: -5046 | I21: -2143 | J21: -1397 | K21: -4542
A22: Accounts payable | B22: 110 | C22: 731 | D22: 1067 | E22: 428 | F22: 694 | G22: 283 | H22: 707 | I22: 664 | J22: 359 | K22: 907
A23: Accrued expenses and other liabilities | B23: 1515 | C23: 4891 | D23: 8614 | E23: 7170 | F23: 5504 | G23: 7304 | H23: 3915 | I23: 3937 | J23: -1161 | K23: 12939
A24: Accrued revenue share | B24: 593 | C24: 955 | D24: 483 | E24: 1273 | F24: 1639 | G24: 1682 | H24: -445 | I24: 482 | J24: 1059 | K24: 899
A25: Deferred revenue | B25: 223 | C25: 390 | D25: 371 | E25: 37 | F25: 635 | G25: 774 | H25: 367 | I25: 525 | J25: 1043 | K25: 2420
A26: Net cash provided by operating activities | B26: 36036 | C26: 37091 | D26: 47971 | E26: 54520 | F26: 65124 | G26: 91652 | H26: 91495 | I26: 101746 | J26: 125299 | K26: 164713
A28: INVESTING ACTIVITIES
A29: Purchases of property and equipment | B29: -10212 | C29: -13184 | D29: -25139 | E29: -23548 | F29: -22281 | G29: -24640 | H29: -31485 | I29: -32251 | J29: -52535 | K29: -91447
A30: Proceeds from disposals of property and equipment | B30: 240
A31: Purchases of marketable securities | B31: -84509 | C31: -92195 | D31: -50158 | E31: -100315 | F31: -136576 | G31: -135196 | H31: -78874 | I31: -77858 | J31: -86679 | K31: -103773
A32: Maturities and sales of marketable securities | B32: 66895 | C32: 73959 | D32: 48507 | E32: 97825 | F32: 132906 | G32: 128294 | H32: 97822 | I32: 86672 | J32: 103428 | K32: 83240
A33: Purchases of non-marketable securities | B33: -1109 | C33: -1745 | D33: -2073 | E33: -1932 | F33: -7175 | G33: -2838 | H33: -2531 | I33: -3027 | J33: -5034 | K33: -5716
A34: Maturities and sales of non-marketable securities | B34: 494 | C34: 533 | D34: 1752 | E34: 405 | F34: 1023 | G34: 934 | H34: 150 | I34: 947 | J34: 882 | K34: 1367
A35: Cash collateral related to securities lending | B35: -2428
A36: Investments in reverse repurchase agreements | B36: 450
A37: Acquisitions, net of cash acquired, and purchases of intangible and other assets | B37: -986 | C37: -287 | D37: -1491 | E37: -2515 | F37: -738 | G37: -2618 | H37: -6969 | I37: -495 | J37: -2931 | K37: -1592
A38: Proceeds from collection of notes receivable | B38: 0 | C38: 1419 | D38: 0
A39: Other investing activities | C39: 99 | D39: 98 | E39: 589 | F39: 68 | G39: 541 | H39: 1589 | I39: -1051 | J39: -2667 | K39: -2370
A40: Net cash used in investing activities | B40: -31165 | C40: -31401 | D40: -28504 | E40: -29491 | F40: -32773 | G40: -35523 | H40: -20298 | I40: -27063 | J40: -45536 | K40: -120291
A42: FINANCING ACTIVITIES
A43: Net payments related to stock-based award activities | B43: -3304 | C43: -4166 | D43: -4993 | E43: -4765 | F43: -5720 | G43: -10162 | H43: -9300 | I43: -9837 | J43: -12190 | K43: -14167
...

Sheet Condensed Financials
A1: Alphabet Inc. (GOOGL) — Condensed Financials
A2: NOPAT, Operating/Financial Classification, NOA/Net Debt/Equity
A3: Aggregates driven by the interactive classification table (rows 49+); values linked to source tabs
A5: Line Item | B5: ='Income Statement'!B6 | C5: ='Income Statement'!C6 | D5: ='Income Statement'!D6 | E5: ='Income Statement'!E6 | F5: ='Income Statement'!F6 | G5: ='Income Statement'!G6 | H5: ='Income Statement'!H6 | I5: ='Income Statement'!I6 | ... K5: ='Income Statement'!K6
A7: A. CONDENSED INCOME STATEMENT
A8: Net Income | B8: ='Income Statement'!B19 | C8: ='Income Statement'!C19 | D8: ='Income Statement'!D19 | E8: ='Income Statement'!E19 | F8: ='Income Statement'!F19 | G8: ='Income Statement'!G19 | H8: ='Income Statement'!H19 | I8: ='Income Statement'!I19 | ... K8: ='Income Statement'!K19
A9: Other Income (Expense), Net | B9: ='Income Statement'!B16 | C9: ='Income Statement'!C16 | D9: ='Income Statement'!D16 | E9: ='Income Statement'!E16 | F9: ='Income Statement'!F16 | G9: ='Income Statement'!G16 | H9: ='Income Statement'!H16 | I9: ='Income Statement'!I16 | ... K9: ='Income Statement'!K16
A10: Interest Expense (estimated) | B10: 124 | C10: 109 | D10: 114 | E10: 100 | F10: 135 | G10: 346 | H10: 357 | I10: 308 | J10: 365 | K10: 1200
A11: Interest Income (estimated) | B11: 1220 | C11: 1312 | D11: 1878 | E11: 2427 | F11: 1865 | G11: 1499 | H11: 1268 | I11: 3865 | J11: 4963 | K11: 4801
A12: Net Interest Expense (Income) | B12: =B10-B11 | C12: =C10-C11 | D12: =D10-D11 | E12: =E10-E11 | F12: =F10-F11 | G12: =G10-G11 | H12: =H10-H11 | I12: =I10-I11 | ... K12: =K10-K11
A13: Pretax Income | B13: ='Income Statement'!B17 | C13: ='Income Statement'!C17 | D13: ='Income Statement'!D17 | E13: ='Income Statement'!E17 | F13: ='Income Statement'!F17 | G13: ='Income Statement'!G17 | H13: ='Income Statement'!H17 | I13: ='Income Statement'!I17 | ... K13: ='Income Statement'!K17
A14: Tax Expense | B14: =ABS('Income Statement'!B18) | C14: =ABS('Income Statement'!C18) | D14: =ABS('Income Statement'!D18) | E14: =ABS('Income Statement'!E18) | F14: =ABS('Income Statement'!F18) | G14: =ABS('Income Statement'!G18) | H14: =ABS('Income Statement'!H18) | I14: =ABS('Income Statement'!I18) | ... K14: =ABS('Income Statement'!K18)
A15: Effective Tax Rate | B15: =IFERROR(B14/B13,0) | C15: =IFERROR(C14/C13,0) | D15: =IFERROR(D14/D13,0) | E15: =IFERROR(E14/E13,0) | F15: =IFERROR(F14/F13,0) | G15: =IFERROR(G14/G13,0) | H15: =IFERROR(H14/H13,0) | I15: =IFERROR(I14/I13,0) | ... K15: =IFERROR(K14/K13,0)
A16: Net Interest After Tax | B16: =B12*(1-B15) | C16: =C12*(1-C15) | D16: =D12*(1-D15) | E16: =E12*(1-E15) | F16: =F12*(1-F15) | G16: =G12*(1-G15) | H16: =H12*(1-H15) | I16: =I12*(1-I15) | ... K16: =K12*(1-K15)
A17: NOPAT | B17: =B8+B16 | C17: =C8+C16 | D17: =D8+D16 | E17: =E8+E16 | F17: =F8+F16 | G17: =G8+G16 | H17: =H8+H16 | I17: =I8+I16 | ... K17: =K8+K16
A18: Interest rows: FY2016-FY2020 as disclosed (XBRL InterestExpense / InterestIncomeOther); FY2021-FY2025 estimated from filing disclosures.
A20: B. CONDENSED BALANCE SHEET
A21: All aggregates below are SUMIFs over the CLASSIFICATION TABLE (rows 51-78). Toggle any item’s classification in column L of the table; NOWC, NOA, Net Debt, DuPont ratios and model anchors recompute.
A25: Operating Working Capital Assets | B25: =SUMIF($L$51:$L$78,"Operating Working Capital Asset",B$51:B$78) | C25: =SUMIF($L$51:$L$78,"Operating Working Capital Asset",C$51:C$78) | D25: =SUMIF($L$51:$L$78,"Operating Working Capital Asset",D$51:D$78) | E25: =SUMIF($L$51:$L$78,"Operating Working Capital Asset",E$51:E$78) | F25: =SUMIF($L$51:$L$78,"Operating Working Capital Asset",F$51:F$78) | G25: =SUMIF($L$51:$L$78,"Operating Working Capital Asset",G$51:G$78) | H25: =SUMIF($L$51:$L$78,"Operating Working Capital Asset",H$51:H$78) | I25: =SUMIF($L$51:$L$78,"Operating Working Capital Asset",I$51:I$78) | ... K25: =SUMIF($L$51:$L$78,"Operating Working Capital Asset",K$51:K$78)
A26: Operating Working Capital Liabilities | B26: =SUMIF($L$51:$L$78,"Operating Working Capital Liability",B$51:B$78) | C26: =SUMIF($L$51:$L$78,"Operating Working Capital Liability",C$51:C$78) | D26: =SUMIF($L$51:$L$78,"Operating Working Capital Liability",D$51:D$78) | E26: =SUMIF($L$51:$L$78,"Operating Working Capital Liability",E$51:E$78) | F26: =SUMIF($L$51:$L$78,"Operating Working Capital Liability",F$51:F$78) | G26: =SUMIF($L$51:$L$78,"Operating Working Capital Liability",G$51:G$78) | H26: =SUMIF($L$51:$L$78,"Operating Working Capital Liability",H$51:H$78) | I26: =SUMIF($L$51:$L$78,"Operating Working Capital Liability",I$51:I$78) | ... K26: =SUMIF($L$51:$L$78,"Operating Working Capital Liability",K$51:K$78)
A27: NET OPERATING WORKING CAPITAL (NOWC) | B27: =B25-B26 | C27: =C25-C26 | D27: =D25-D26 | E27: =E25-E26 | F27: =F25-F26 | G27: =G25-G26 | H27: =H25-H26 | I27: =I25-I26 | ... K27: =K25-K26
A29: Operating Long-Term Assets | B29: =SUMIF($L$51:$L$78,"Operating Long-Term Asset",B$51:B$78) | C29: =SUMIF($L$51:$L$78,"Operating Long-Term Asset",C$51:C$78) | D29: =SUMIF($L$51:$L$78,"Operating Long-Term Asset",D$51:D$78) | E29: =SUMIF($L$51:$L$78,"Operating Long-Term Asset",E$51:E$78) | F29: =SUMIF($L$51:$L$78,"Operating Long-Term Asset",F$51:F$78) | G29: =SUMIF($L$51:$L$78,"Operating Long-Term Asset",G$51:G$78) | H29: =SUMIF($L$51:$L$78,"Operating Long-Term Asset",H$51:H$78) | I29: =SUMIF($L$51:$L$78,"Operating Long-Term Asset",I$51:I$78) | ... K29: =SUMIF($L$51:$L$78,"Operating Long-Term Asset",K$51:K$78)
A30: Operating Long-Term Liabilities | B30: =SUMIF($L$51:$L$78,"Operating Long-Term Liability",B$51:B$78) | C30: =SUMIF($L$51:$L$78,"Operating Long-Term Liability",C$51:C$78) | D30: =SUMIF($L$51:$L$78,"Operating Long-Term Liability",D$51:D$78) | E30: =SUMIF($L$51:$L$78,"Operating Long-Term Liability",E$51:E$78) | F30: =SUMIF($L$51:$L$78,"Operating Long-Term Liability",F$51:F$78) | G30: =SUMIF($L$51:$L$78,"Operating Long-Term Liability",G$51:G$78) | H30: =SUMIF($L$51:$L$78,"Operating Long-Term Liability",H$51:H$78) | I30: =SUMIF($L$51:$L$78,"Operating Long-Term Liability",I$51:I$78) | ... K30: =SUMIF($L$51:$L$78,"Operating Long-Term Liability",K$51:K$78)
A31: NET OPERATING LT ASSETS | B31: =B29-B30 | C31: =C29-C30 | D31: =D29-D30 | E31: =E29-E30 | F31: =F29-F30 | G31: =G29-G30 | H31: =H29-H30 | I31: =I29-I30 | ... K31: =K29-K30
A33: NET OPERATING ASSETS (NOA) | B33: =B27+B31 | C33: =C27+C31 | D33: =D27+D31 | E33: =E27+E31 | F33: =F27+F31 | G33: =G27+G31 | H33: =H27+H31 | I33: =I27+I31 | ... K33: =K27+K31
A35: Financial Assets | B35: =SUMIF($L$51:$L$78,"Financial Asset",B$51:B$78) | C35: =SUMIF($L$51:$L$78,"Financial Asset",C$51:C$78) | D35: =SUMIF($L$51:$L$78,"Financial Asset",D$51:D$78) | E35: =SUMIF($L$51:$L$78,"Financial Asset",E$51:E$78) | F35: =SUMIF($L$51:$L$78,"Financial Asset",F$51:F$78) | G35: =SUMIF($L$51:$L$78,"Financial Asset",G$51:G$78) | H35: =SUMIF($L$51:$L$78,"Financial Asset",H$51:H$78) | I35: =SUMIF($L$51:$L$78,"Financial Asset",I$51:I$78) | ... K35: =SUMIF($L$51:$L$78,"Financial Asset",K$51:K$78)
A36: Financial Liabilities | B36: =SUMIF($L$51:$L$78,"Financial Liability",B$51:B$78) | C36: =SUMIF($L$51:$L$78,"Financial Liability",C$51:C$78) | D36: =SUMIF($L$51:$L$78,"Financial Liability",D$51:D$78) | E36: =SUMIF($L$51:$L$78,"Financial Liability",E$51:E$78) | F36: =SUMIF($L$51:$L$78,"Financial Liability",F$51:F$78) | G36: =SUMIF($L$51:$L$78,"Financial Liability",G$51:G$78) | H36: =SUMIF($L$51:$L$78,"Financial Liability",H$51:H$78) | I36: =SUMIF($L$51:$L$78,"Financial Liability",I$51:I$78) | ... K36: =SUMIF($L$51:$L$78,"Financial Liability",K$51:K$78)
A37: NET DEBT (Fin Liab - Fin Assets) | B37: =B36-B35 | C37: =C36-C35 | D37: =D36-D35 | E37: =E36-E35 | F37: =F36-F35 | G37: =G36-G35 | H37: =H36-H35 | I37: =I36-I35 | ... K37: =K36-K35
A38: NOTE: Negative Net Debt = net cash position (Fin Assets > Fin Liab)
A40: EQUITY (NOA - Net Debt) | B40: =B33-B37 | C40: =C33-C37 | D40: =D33-D37 | E40: =E33-E37 | F40: =F33-F37 | G40: =G33-G37 | H40: =H33-H37 | I40: =I33-I37 | ... K40: =K33-K37
A41: Reported Equity | B41: ='Balance Sheet'!B48 | C41: ='Balance Sheet'!C48 | D41: ='Balance Sheet'!D48 | E41: ='Balance Sheet'!E48 | F41: ='Balance Sheet'!F48 | G41: ='Balance Sheet'!G48 | H41: ='Balance Sheet'!H48 | I41: ='Balance Sheet'!I48 | ... K41: ='Balance Sheet'!K48
A44: TOTAL CAPITAL (Net Debt + Equity) | B44: =B37+B40 | C44: =C37+C40 | D44: =D37+D40 | E44: =E37+E40 | F44: =F37+F40 | G44: =G37+G40 | H44: =H37+H40 | I44: =I37+I40 | ... K44: =K37+K40
A45: CHECK: implied equity = reported equity | B45: =IF(ABS(B40-B41)<1,"OK","CHECK") | C45: =IF(ABS(C40-C41)<1,"OK","CHECK") | D45: =IF(ABS(D40-D41)<1,"OK","CHECK") | E45: =IF(ABS(E40-E41)<1,"OK","CHECK") | F45: =IF(ABS(F40-F41)<1,"OK","CHECK") | G45: =IF(ABS(G40-G41)<1,"OK","CHECK") | H45: =IF(ABS(H40-H41)<1,"OK","CHECK") | I45: =IF(ABS(I40-I41)<1,"OK","CHECK") | ... K45: =IF(ABS(K40-K41)<1,"OK","CHECK")
A49: C. BALANCE SHEET CLASSIFICATION TABLE (interactive) | L49: ▼ TOGGLE HERE: click any cell below — a dropdown menu appears
A50: Line Item | B50: ='Balance Sheet'!B6 | C50: ='Balance Sheet'!C6 | D50: ='Balance Sheet'!D6 | E50: ='Balance Sheet'!E6 | F50: ='Balance Sheet'!F6 | G50: ='Balance Sheet'!G6 | H50: ='Balance Sheet'!H6 | I50: ='Balance Sheet'!I6 | ... K50: ='Balance Sheet'!K6 | L50: Classification (click → ▼) | M50: Notes
A51: Cash and cash equivalents | B51: ='Balance Sheet'!B8 | C51: ='Balance Sheet'!C8 | D51: ='Balance Sheet'!D8 | E51: ='Balance Sheet'!E8 | F51: ='Balance Sheet'!F8 | G51: ='Balance Sheet'!G8 | H51: ='Balance Sheet'!H8 | I51: ='Balance Sheet'!I8 | ... K51: ='Balance Sheet'!K8 | L51: Financial Asset
A52: Marketable securities | B52: ='Balance Sheet'!B9 | C52: ='Balance Sheet'!C9 | D52: ='Balance Sheet'!D9 | E52: ='Balance Sheet'!E9 | F52: ='Balance Sheet'!F9 | G52: ='Balance Sheet'!G9 | H52: ='Balance Sheet'!H9 | I52: ='Balance Sheet'!I9 | ... K52: ='Balance Sheet'!K9 | L52: Financial Asset
A53: Accounts receivable, net | B53: ='Balance Sheet'!B10 | C53: ='Balance Sheet'!C10 | D53: ='Balance Sheet'!D10 | E53: ='Balance Sheet'!E10 | F53: ='Balance Sheet'!F10 | G53: ='Balance Sheet'!G10 | H53: ='Balance Sheet'!H10 | I53: ='Balance Sheet'!I10 | ... K53: ='Balance Sheet'!K10 | L53: Operating Working Capital Asset
A54: Income taxes receivable, net | B54: ='Balance Sheet'!B11 | C54: ='Balance Sheet'!C11 | D54: ='Balance Sheet'!D11 | E54: ='Balance Sheet'!E11 | F54: ='Balance Sheet'!F11 | G54: ='Balance Sheet'!G11 | H54: ='Balance Sheet'!H11 | I54: ='Balance Sheet'!I11 | ... K54: ='Balance Sheet'!K11 | L54: Operating Working Capital Asset
A55: Inventory | B55: ='Balance Sheet'!B12 | C55: ='Balance Sheet'!C12 | D55: ='Balance Sheet'!D12 | E55: ='Balance Sheet'!E12 | F55: ='Balance Sheet'!F12 | G55: ='Balance Sheet'!G12 | H55: ='Balance Sheet'!H12 | I55: ='Balance Sheet'!I12 | ... K55: ='Balance Sheet'!K12 | L55: Operating Working Capital Asset
...

Sheet ALT DuPont
A1: Alphabet Inc. (GOOGL) — Alternative DuPont Decomposition
A2: ROE = RNOA + FLEV × Spread
A3: All values linked to Condensed Financials
A5: Metric | B5: ='Income Statement'!B6 | C5: ='Income Statement'!C6 | D5: ='Income Statement'!D6 | E5: ='Income Statement'!E6 | F5: ='Income Statement'!F6 | G5: ='Income Statement'!G6 | H5: ='Income Statement'!H6 | I5: ='Income Statement'!I6 | ... K5: ='Income Statement'!K6
A7: Revenue | B7: ='Income Statement'!B7 | C7: ='Income Statement'!C7 | D7: ='Income Statement'!D7 | E7: ='Income Statement'!E7 | F7: ='Income Statement'!F7 | G7: ='Income Statement'!G7 | H7: ='Income Statement'!H7 | I7: ='Income Statement'!I7 | ... K7: ='Income Statement'!K7
A8: NOPAT | B8: ='Condensed Financials'!B17 | C8: ='Condensed Financials'!C17 | D8: ='Condensed Financials'!D17 | E8: ='Condensed Financials'!E17 | F8: ='Condensed Financials'!F17 | G8: ='Condensed Financials'!G17 | H8: ='Condensed Financials'!H17 | I8: ='Condensed Financials'!I17 | ... K8: ='Condensed Financials'!K17
A9: Net Income | B9: ='Condensed Financials'!B8 | C9: ='Condensed Financials'!C8 | D9: ='Condensed Financials'!D8 | E9: ='Condensed Financials'!E8 | F9: ='Condensed Financials'!F8 | G9: ='Condensed Financials'!G8 | H9: ='Condensed Financials'!H8 | I9: ='Condensed Financials'!I8 | ... K9: ='Condensed Financials'!K8
A10: Net Interest After Tax | B10: ='Condensed Financials'!B16 | C10: ='Condensed Financials'!C16 | D10: ='Condensed Financials'!D16 | E10: ='Condensed Financials'!E16 | F10: ='Condensed Financials'!F16 | G10: ='Condensed Financials'!G16 | H10: ='Condensed Financials'!H16 | I10: ='Condensed Financials'!I16 | ... K10: ='Condensed Financials'!K16
A12: NOA (Beginning) | B12: n/a | C12: ='Condensed Financials'!B33 | D12: ='Condensed Financials'!C33 | E12: ='Condensed Financials'!D33 | F12: ='Condensed Financials'!E33 | G12: ='Condensed Financials'!F33 | H12: ='Condensed Financials'!G33 | I12: ='Condensed Financials'!H33 | J12: ='Condensed Financials'!I33 | K12: ='Condensed Financials'!J33
A13: Net Debt (Beginning) | B13: n/a | C13: ='Condensed Financials'!B37 | D13: ='Condensed Financials'!C37 | E13: ='Condensed Financials'!D37 | F13: ='Condensed Financials'!E37 | G13: ='Condensed Financials'!F37 | H13: ='Condensed Financials'!G37 | I13: ='Condensed Financials'!H37 | J13: ='Condensed Financials'!I37 | K13: ='Condensed Financials'!J37
A14: Equity (Beginning) | B14: n/a | C14: ='Condensed Financials'!B40 | D14: ='Condensed Financials'!C40 | E14: ='Condensed Financials'!D40 | F14: ='Condensed Financials'!E40 | G14: ='Condensed Financials'!F40 | H14: ='Condensed Financials'!G40 | I14: ='Condensed Financials'!H40 | J14: ='Condensed Financials'!I40 | K14: ='Condensed Financials'!J40
A16: Sales Growth | B16: n/a | C16: =C7/B7-1 | D16: =D7/C7-1 | E16: =E7/D7-1 | F16: =F7/E7-1 | G16: =G7/F7-1 | H16: =H7/G7-1 | I16: =I7/H7-1 | J16: =J7/I7-1 | K16: =K7/J7-1
A17: NOPAT Margin | B17: =IFERROR(B8/B7,0) | C17: =IFERROR(C8/C7,0) | D17: =IFERROR(D8/D7,0) | E17: =IFERROR(E8/E7,0) | F17: =IFERROR(F8/F7,0) | G17: =IFERROR(G8/G7,0) | H17: =IFERROR(H8/H7,0) | I17: =IFERROR(I8/I7,0) | ... K17: =IFERROR(K8/K7,0)
A18: Avg NOA | B18: n/a | C18: =('Condensed Financials'!C33+'Condensed Financials'!B33)/2 | D18: =('Condensed Financials'!D33+'Condensed Financials'!C33)/2 | E18: =('Condensed Financials'!E33+'Condensed Financials'!D33)/2 | F18: =('Condensed Financials'!F33+'Condensed Financials'!E33)/2 | G18: =('Condensed Financials'!G33+'Condensed Financials'!F33)/2 | H18: =('Condensed Financials'!H33+'Condensed Financials'!G33)/2 | I18: =('Condensed Financials'!I33+'Condensed Financials'!H33)/2 | J18: =('Condensed Financials'!J33+'Condensed Financials'!I33)/2 | K18: =('Condensed Financials'!K33+'Condensed Financials'!J33)/2
A19: Asset Turnover (Revenue / Avg NOA) | B19: n/a | C19: =IFERROR(C7/C18,0) | D19: =IFERROR(D7/D18,0) | E19: =IFERROR(E7/E18,0) | F19: =IFERROR(F7/F18,0) | G19: =IFERROR(G7/G18,0) | H19: =IFERROR(H7/H18,0) | I19: =IFERROR(I7/I18,0) | J19: =IFERROR(J7/J18,0) | K19: =IFERROR(K7/K18,0)
A20: RNOA (NOPAT Margin × Turnover) | B20: n/a | C20: =C17*C19 | D20: =D17*D19 | E20: =E17*E19 | F20: =F17*F19 | G20: =G17*G19 | H20: =H17*H19 | I20: =I17*I19 | J20: =J17*J19 | K20: =K17*K19
A22: Avg Net Debt | B22: n/a | C22: =('Condensed Financials'!C37+'Condensed Financials'!B37)/2 | D22: =('Condensed Financials'!D37+'Condensed Financials'!C37)/2 | E22: =('Condensed Financials'!E37+'Condensed Financials'!D37)/2 | F22: =('Condensed Financials'!F37+'Condensed Financials'!E37)/2 | G22: =('Condensed Financials'!G37+'Condensed Financials'!F37)/2 | H22: =('Condensed Financials'!H37+'Condensed Financials'!G37)/2 | I22: =('Condensed Financials'!I37+'Condensed Financials'!H37)/2 | J22: =('Condensed Financials'!J37+'Condensed Financials'!I37)/2 | K22: =('Condensed Financials'!K37+'Condensed Financials'!J37)/2
A23: After-tax Cost of Debt | B23: n/a | C23: =IFERROR(C10/C22,0) | D23: =IFERROR(D10/D22,0) | E23: =IFERROR(E10/E22,0) | F23: =IFERROR(F10/F22,0) | G23: =IFERROR(G10/G22,0) | H23: =IFERROR(H10/H22,0) | I23: =IFERROR(I10/I22,0) | J23: =IFERROR(J10/J22,0) | K23: =IFERROR(K10/K22,0)
A24: Spread (RNOA - Cost of Debt) | B24: n/a | C24: =C20-C23 | D24: =D20-D23 | E24: =E20-E23 | F24: =F20-F23 | G24: =G20-G23 | H24: =H20-H23 | I24: =I20-I23 | J24: =J20-J23 | K24: =K20-K23
A25: Avg Equity | B25: n/a | C25: =('Condensed Financials'!C40+'Condensed Financials'!B40)/2 | D25: =('Condensed Financials'!D40+'Condensed Financials'!C40)/2 | E25: =('Condensed Financials'!E40+'Condensed Financials'!D40)/2 | F25: =('Condensed Financials'!F40+'Condensed Financials'!E40)/2 | G25: =('Condensed Financials'!G40+'Condensed Financials'!F40)/2 | H25: =('Condensed Financials'!H40+'Condensed Financials'!G40)/2 | I25: =('Condensed Financials'!I40+'Condensed Financials'!H40)/2 | J25: =('Condensed Financials'!J40+'Condensed Financials'!I40)/2 | K25: =('Condensed Financials'!K40+'Condensed Financials'!J40)/2
A26: Net Financial Leverage (Avg ND / Avg Eq) | B26: n/a | C26: =IFERROR(C22/C25,0) | D26: =IFERROR(D22/D25,0) | E26: =IFERROR(E22/E25,0) | F26: =IFERROR(F22/F25,0) | G26: =IFERROR(G22/G25,0) | H26: =IFERROR(H22/H25,0) | I26: =IFERROR(I22/I25,0) | J26: =IFERROR(J22/J25,0) | K26: =IFERROR(K22/K25,0)
A27: Financial Leverage Gain (Spread × FLEV) | B27: n/a | C27: =C24*C26 | D27: =D24*D26 | E27: =E24*E26 | F27: =F24*F26 | G27: =G24*G26 | H27: =H24*H26 | I27: =I24*I26 | J27: =J24*J26 | K27: =K24*K26
A29: ROE (Decomposed) = RNOA + Fin Lev Gain | B29: n/a | C29: =C20+C27 | D29: =D20+D27 | E29: =E20+E27 | F29: =F20+F27 | G29: =G20+G27 | H29: =H20+H27 | I29: =I20+I27 | J29: =J20+J27 | K29: =K20+K27
A30: Actual ROE (NI / Avg Equity) | B30: n/a | C30: =IFERROR(C9/C25,0) | D30: =IFERROR(D9/D25,0) | E30: =IFERROR(E9/E25,0) | F30: =IFERROR(F9/F25,0) | G30: =IFERROR(G9/G25,0) | H30: =IFERROR(H9/H25,0) | I30: =IFERROR(I9/I25,0) | J30: =IFERROR(J9/J25,0) | K30: =IFERROR(K9/K25,0)
A31: CHECK: |Decomp - Actual| < 0.1% | B31: n/a | C31: =IF(ABS(C29-C30)<0.001,"OK","CHECK") | D31: =IF(ABS(D29-D30)<0.001,"OK","CHECK") | E31: =IF(ABS(E29-E30)<0.001,"OK","CHECK") | F31: =IF(ABS(F29-F30)<0.001,"OK","CHECK") | G31: =IF(ABS(G29-G30)<0.001,"OK","CHECK") | H31: =IF(ABS(H29-H30)<0.001,"OK","CHECK") | I31: =IF(ABS(I29-I30)<0.001,"OK","CHECK") | J31: =IF(ABS(J29-J30)<0.001,"OK","CHECK") | K31: =IF(ABS(K29-K30)<0.001,"OK","CHECK")
A33: QUARTERLY DUPONT (FLOWS ANNUALIZED ×4)
A34: Quarterly NOPAT/NIAT/NI are annualized (×4) against average positions; Sales Growth is QoQ (not seasonally adjusted). The first quarter column's averages use the FY2023 annual Condensed column (I) as the prior period.
B36: Q1 2024 | C36: Q2 2024 | D36: Q3 2024 | E36: Q4 2024 | F36: Q1 2025 | G36: Q2 2025 | H36: Q3 2025 | I36: Q4 2025 | J36: Q1 2026
A37: Line Item | B37: ='Income Statement'!B32 | C37: ='Income Statement'!C32 | D37: ='Income Statement'!D32 | E37: ='Income Statement'!E32 | F37: ='Income Statement'!F32 | G37: ='Income Statement'!G32 | H37: ='Income Statement'!H32 | I37: ='Income Statement'!I32 | J37: ='Income Statement'!J32
A38: Sales Growth (QoQ) | B38: n/a | C38: ='Income Statement'!C34/'Income Statement'!B34-1 | D38: ='Income Statement'!D34/'Income Statement'!C34-1 | E38: ='Income Statement'!E34/'Income Statement'!D34-1 | F38: ='Income Statement'!F34/'Income Statement'!E34-1 | G38: ='Income Statement'!G34/'Income Statement'!F34-1 | H38: ='Income Statement'!H34/'Income Statement'!G34-1 | I38: ='Income Statement'!I34/'Income Statement'!H34-1 | J38: ='Income Statement'!J34/'Income Statement'!I34-1
A39: NOPAT Margin (quarter) | B39: ='Condensed Financials'!B94/'Income Statement'!B34 | C39: ='Condensed Financials'!C94/'Income Statement'!C34 | D39: ='Condensed Financials'!D94/'Income Statement'!D34 | E39: ='Condensed Financials'!E94/'Income Statement'!E34 | F39: ='Condensed Financials'!F94/'Income Statement'!F34 | G39: ='Condensed Financials'!G94/'Income Statement'!G34 | H39: ='Condensed Financials'!H94/'Income Statement'!H34 | I39: ='Condensed Financials'!I94/'Income Statement'!I34 | J39: ='Condensed Financials'!J94/'Income Statement'!J34
A40: Avg NOA | B40: =('Condensed Financials'!B103+'Condensed Financials'!I33)/2 | C40: =('Condensed Financials'!C103+'Condensed Financials'!B103)/2 | D40: =('Condensed Financials'!D103+'Condensed Financials'!C103)/2 | E40: =('Condensed Financials'!E103+'Condensed Financials'!D103)/2 | F40: =('Condensed Financials'!F103+'Condensed Financials'!E103)/2 | G40: =('Condensed Financials'!G103+'Condensed Financials'!F103)/2 | H40: =('Condensed Financials'!H103+'Condensed Financials'!G103)/2 | I40: =('Condensed Financials'!I103+'Condensed Financials'!H103)/2 | J40: =('Condensed Financials'!J103+'Condensed Financials'!I103)/2
A41: Asset Turnover (annualized) | B41: ='Income Statement'!B34*4/B40 | C41: ='Income Statement'!C34*4/C40 | D41: ='Income Statement'!D34*4/D40 | E41: ='Income Statement'!E34*4/E40 | F41: ='Income Statement'!F34*4/F40 | G41: ='Income Statement'!G34*4/G40 | H41: ='Income Statement'!H34*4/H40 | I41: ='Income Statement'!I34*4/I40 | J41: ='Income Statement'!J34*4/J40
A42: RNOA (annualized) | B42: =B39*B41 | C42: =C39*C41 | D42: =D39*D41 | E42: =E39*E41 | F42: =F39*F41 | G42: =G39*G41 | H42: =H39*H41 | I42: =I39*I41 | J42: =J39*J41
A43: Avg Net Debt | B43: =('Condensed Financials'!B106+'Condensed Financials'!I37)/2 | C43: =('Condensed Financials'!C106+'Condensed Financials'!B106)/2 | D43: =('Condensed Financials'!D106+'Condensed Financials'!C106)/2 | E43: =('Condensed Financials'!E106+'Condensed Financials'!D106)/2 | F43: =('Condensed Financials'!F106+'Condensed Financials'!E106)/2 | G43: =('Condensed Financials'!G106+'Condensed Financials'!F106)/2 | H43: =('Condensed Financials'!H106+'Condensed Financials'!G106)/2 | I43: =('Condensed Financials'!I106+'Condensed Financials'!H106)/2 | J43: =('Condensed Financials'!J106+'Condensed Financials'!I106)/2
A44: After-tax Cost of Debt (annualized) | B44: =IFERROR('Condensed Financials'!B93*4/B43,0) | C44: =IFERROR('Condensed Financials'!C93*4/C43,0) | D44: =IFERROR('Condensed Financials'!D93*4/D43,0) | E44: =IFERROR('Condensed Financials'!E93*4/E43,0) | F44: =IFERROR('Condensed Financials'!F93*4/F43,0) | G44: =IFERROR('Condensed Financials'!G93*4/G43,0) | H44: =IFERROR('Condensed Financials'!H93*4/H43,0) | I44: =IFERROR('Condensed Financials'!I93*4/I43,0) | J44: =IFERROR('Condensed Financials'!J93*4/J43,0)
A45: Spread (RNOA - Cost of Debt) | B45: =B42-B44 | C45: =C42-C44 | D45: =D42-D44 | E45: =E42-E44 | F45: =F42-F44 | G45: =G42-G44 | H45: =H42-H44 | I45: =I42-I44 | J45: =J42-J44
A46: Avg Equity | B46: =('Condensed Financials'!B107+'Condensed Financials'!I40)/2 | C46: =('Condensed Financials'!C107+'Condensed Financials'!B107)/2 | D46: =('Condensed Financials'!D107+'Condensed Financials'!C107)/2 | E46: =('Condensed Financials'!E107+'Condensed Financials'!D107)/2 | F46: =('Condensed Financials'!F107+'Condensed Financials'!E107)/2 | G46: =('Condensed Financials'!G107+'Condensed Financials'!F107)/2 | H46: =('Condensed Financials'!H107+'Condensed Financials'!G107)/2 | I46: =('Condensed Financials'!I107+'Condensed Financials'!H107)/2 | J46: =('Condensed Financials'!J107+'Condensed Financials'!I107)/2
A47: Net Financial Leverage (Avg ND / Avg Eq) | B47: =IFERROR(B43/B46,0) | C47: =IFERROR(C43/C46,0) | D47: =IFERROR(D43/D46,0) | E47: =IFERROR(E43/E46,0) | F47: =IFERROR(F43/F46,0) | G47: =IFERROR(G43/G46,0) | H47: =IFERROR(H43/H46,0) | I47: =IFERROR(I43/I46,0) | J47: =IFERROR(J43/J46,0)
A48: Financial Leverage Gain (Spread × FLEV) | B48: =B45*B47 | C48: =C45*C47 | D48: =D45*D47 | E48: =E45*E47 | F48: =F45*F47 | G48: =G45*G47 | H48: =H45*H47 | I48: =I45*I47 | J48: =J45*J47
...

Sheet Earnings Quality
A1: Alphabet Inc. (GOOGL) — Earnings Quality
A2: SCREENS, NOT VERDICTS: thresholds are calibrated on cross-sections; for a mega-cap a flag is a tripwire that demands explanation, not an accusation.
A3: Accruals / M-Score / F-Score are live formulas over the source tabs; Benford rows are script-computed from each filing's FULL XBRL fact set (build_quality.py).
A5: ANNUAL
A6: Line Item | B6: ='Income Statement'!B6 | C6: ='Income Statement'!C6 | D6: ='Income Statement'!D6 | E6: ='Income Statement'!E6 | F6: ='Income Statement'!F6 | G6: ='Income Statement'!G6 | H6: ='Income Statement'!H6 | I6: ='Income Statement'!I6 | ... K6: ='Income Statement'!K6
A8: A. ACCRUALS & CASH CONVERSION
A9: NOA (Condensed) | B9: ='Condensed Financials'!B33 | C9: ='Condensed Financials'!C33 | D9: ='Condensed Financials'!D33 | E9: ='Condensed Financials'!E33 | F9: ='Condensed Financials'!F33 | G9: ='Condensed Financials'!G33 | H9: ='Condensed Financials'!H33 | I9: ='Condensed Financials'!I33 | ... K9: ='Condensed Financials'!K33
A10: BS accruals = dNOA | B10: n/a | C10: =C9-B9 | D10: =D9-C9 | E10: =E9-D9 | F10: =F9-E9 | G10: =G9-F9 | H10: =H9-G9 | I10: =I9-H9 | J10: =J9-I9 | K10: =K9-J9
A11: Avg NOA | B11: n/a | C11: =(C9+B9)/2 | D11: =(D9+C9)/2 | E11: =(E9+D9)/2 | F11: =(F9+E9)/2 | G11: =(G9+F9)/2 | H11: =(H9+G9)/2 | I11: =(I9+H9)/2 | J11: =(J9+I9)/2 | K11: =(K9+J9)/2
A12: Scaled BS accruals (dNOA/avg NOA) | B12: n/a | C12: =C10/C11 | D12: =D10/D11 | E12: =E10/E11 | F12: =F10/F11 | G12: =G10/G11 | H12: =H10/H11 | I12: =I10/I11 | J12: =J10/J11 | K12: =K10/K11 | L12: High positive accruals with weak cash conversion = the classic earnings-quality red flag (Sloan 1996). GOOGL's NI carries large NON-cash unrealized securities gains (see Core Earnings Bridge) - they inflate income accruals mechanically
A13: Net income | B13: ='Income Statement'!B19 | C13: ='Income Statement'!C19 | D13: ='Income Statement'!D19 | E13: ='Income Statement'!E19 | F13: ='Income Statement'!F19 | G13: ='Income Statement'!G19 | H13: ='Income Statement'!H19 | I13: ='Income Statement'!I19 | ... K13: ='Income Statement'!K19
A14: CFO | B14: ='Cash Flow Statement'!B26 | C14: ='Cash Flow Statement'!C26 | D14: ='Cash Flow Statement'!D26 | E14: ='Cash Flow Statement'!E26 | F14: ='Cash Flow Statement'!F26 | G14: ='Cash Flow Statement'!G26 | H14: ='Cash Flow Statement'!H26 | I14: ='Cash Flow Statement'!I26 | ... K14: ='Cash Flow Statement'!K26
A15: Income accruals = NI - CFO | B15: =B13-B14 | C15: =C13-C14 | D15: =D13-D14 | E15: =E13-E14 | F15: =F13-F14 | G15: =G13-G14 | H15: =H13-H14 | I15: =I13-I14 | ... K15: =K13-K14
A16: Scaled income accruals ((NI-CFO)/avg NOA) | B16: n/a | C16: =C15/C11 | D16: =D15/D11 | E16: =E15/E11 | F16: =F15/F11 | G16: =G15/G11 | H16: =H15/H11 | I16: =I15/I11 | J16: =J15/J11 | K16: =K15/K11
A17: Cash conversion (CFO/NI) | B17: =IFERROR('Cash Flow Statement'!B26/'Income Statement'!B19,"n/m") | C17: =IFERROR('Cash Flow Statement'!C26/'Income Statement'!C19,"n/m") | D17: =IFERROR('Cash Flow Statement'!D26/'Income Statement'!D19,"n/m") | E17: =IFERROR('Cash Flow Statement'!E26/'Income Statement'!E19,"n/m") | F17: =IFERROR('Cash Flow Statement'!F26/'Income Statement'!F19,"n/m") | G17: =IFERROR('Cash Flow Statement'!G26/'Income Statement'!G19,"n/m") | H17: =IFERROR('Cash Flow Statement'!H26/'Income Statement'!H19,"n/m") | I17: =IFERROR('Cash Flow Statement'!I26/'Income Statement'!I19,"n/m") | ... K17: =IFERROR('Cash Flow Statement'!K26/'Income Statement'!K19,"n/m")
A19: B. BENEISH M-SCORE (8-variable, YoY)
A20: DSRI (receivables/sales index) | B20: n/a | C20: =IFERROR(('Balance Sheet'!C10/'Income Statement'!C7)/('Balance Sheet'!B10/'Income Statement'!B7),"n/m") | D20: =IFERROR(('Balance Sheet'!D10/'Income Statement'!D7)/('Balance Sheet'!C10/'Income Statement'!C7),"n/m") | E20: =IFERROR(('Balance Sheet'!E10/'Income Statement'!E7)/('Balance Sheet'!D10/'Income Statement'!D7),"n/m") | F20: =IFERROR(('Balance Sheet'!F10/'Income Statement'!F7)/('Balance Sheet'!E10/'Income Statement'!E7),"n/m") | G20: =IFERROR(('Balance Sheet'!G10/'Income Statement'!G7)/('Balance Sheet'!F10/'Income Statement'!F7),"n/m") | H20: =IFERROR(('Balance Sheet'!H10/'Income Statement'!H7)/('Balance Sheet'!G10/'Income Statement'!G7),"n/m") | I20: =IFERROR(('Balance Sheet'!I10/'Income Statement'!I7)/('Balance Sheet'!H10/'Income Statement'!H7),"n/m") | J20: =IFERROR(('Balance Sheet'!J10/'Income Statement'!J7)/('Balance Sheet'!I10/'Income Statement'!I7),"n/m") | K20: =IFERROR(('Balance Sheet'!K10/'Income Statement'!K7)/('Balance Sheet'!J10/'Income Statement'!J7),"n/m")
A21: GMI (gross margin index) | B21: n/a | C21: =IFERROR(('Income Statement'!B9/'Income Statement'!B7)/('Income Statement'!C9/'Income Statement'!C7),"n/m") | D21: =IFERROR(('Income Statement'!C9/'Income Statement'!C7)/('Income Statement'!D9/'Income Statement'!D7),"n/m") | E21: =IFERROR(('Income Statement'!D9/'Income Statement'!D7)/('Income Statement'!E9/'Income Statement'!E7),"n/m") | F21: =IFERROR(('Income Statement'!E9/'Income Statement'!E7)/('Income Statement'!F9/'Income Statement'!F7),"n/m") | G21: =IFERROR(('Income Statement'!F9/'Income Statement'!F7)/('Income Statement'!G9/'Income Statement'!G7),"n/m") | H21: =IFERROR(('Income Statement'!G9/'Income Statement'!G7)/('Income Statement'!H9/'Income Statement'!H7),"n/m") | I21: =IFERROR(('Income Statement'!H9/'Income Statement'!H7)/('Income Statement'!I9/'Income Statement'!I7),"n/m") | J21: =IFERROR(('Income Statement'!I9/'Income Statement'!I7)/('Income Statement'!J9/'Income Statement'!J7),"n/m") | K21: =IFERROR(('Income Statement'!J9/'Income Statement'!J7)/('Income Statement'!K9/'Income Statement'!K7),"n/m")
A22: AQI (asset quality index) | B22: n/a | C22: =IFERROR((1-('Balance Sheet'!C14+'Balance Sheet'!C19)/'Balance Sheet'!C24)/(1-('Balance Sheet'!B14+'Balance Sheet'!B19)/'Balance Sheet'!B24),"n/m") | D22: =IFERROR((1-('Balance Sheet'!D14+'Balance Sheet'!D19)/'Balance Sheet'!D24)/(1-('Balance Sheet'!C14+'Balance Sheet'!C19)/'Balance Sheet'!C24),"n/m") | E22: =IFERROR((1-('Balance Sheet'!E14+'Balance Sheet'!E19)/'Balance Sheet'!E24)/(1-('Balance Sheet'!D14+'Balance Sheet'!D19)/'Balance Sheet'!D24),"n/m") | F22: =IFERROR((1-('Balance Sheet'!F14+'Balance Sheet'!F19)/'Balance Sheet'!F24)/(1-('Balance Sheet'!E14+'Balance Sheet'!E19)/'Balance Sheet'!E24),"n/m") | G22: =IFERROR((1-('Balance Sheet'!G14+'Balance Sheet'!G19)/'Balance Sheet'!G24)/(1-('Balance Sheet'!F14+'Balance Sheet'!F19)/'Balance Sheet'!F24),"n/m") | H22: =IFERROR((1-('Balance Sheet'!H14+'Balance Sheet'!H19)/'Balance Sheet'!H24)/(1-('Balance Sheet'!G14+'Balance Sheet'!G19)/'Balance Sheet'!G24),"n/m") | I22: =IFERROR((1-('Balance Sheet'!I14+'Balance Sheet'!I19)/'Balance Sheet'!I24)/(1-('Balance Sheet'!H14+'Balance Sheet'!H19)/'Balance Sheet'!H24),"n/m") | J22: =IFERROR((1-('Balance Sheet'!J14+'Balance Sheet'!J19)/'Balance Sheet'!J24)/(1-('Balance Sheet'!I14+'Balance Sheet'!I19)/'Balance Sheet'!I24),"n/m") | K22: =IFERROR((1-('Balance Sheet'!K14+'Balance Sheet'!K19)/'Balance Sheet'!K24)/(1-('Balance Sheet'!J14+'Balance Sheet'!J19)/'Balance Sheet'!J24),"n/m")
A23: SGI (sales growth index) | B23: n/a | C23: ='Income Statement'!C7/'Income Statement'!B7 | D23: ='Income Statement'!D7/'Income Statement'!C7 | E23: ='Income Statement'!E7/'Income Statement'!D7 | F23: ='Income Statement'!F7/'Income Statement'!E7 | G23: ='Income Statement'!G7/'Income Statement'!F7 | H23: ='Income Statement'!H7/'Income Statement'!G7 | I23: ='Income Statement'!I7/'Income Statement'!H7 | J23: ='Income Statement'!J7/'Income Statement'!I7 | K23: ='Income Statement'!K7/'Income Statement'!J7
A24: DEPI (depreciation rate index) | B24: n/a | C24: =IFERROR(((N('Cash Flow Statement'!B10)+N('Cash Flow Statement'!B11)+N('Cash Flow Statement'!B12))/((N('Cash Flow Statement'!B10)+N('Cash Flow Statement'!B11)+N('Cash Flow Statement'!B12))+'Balance Sheet'!B19))/((N('Cash Flow Statement'!C10)+N('Cash Flow Statement'!C11)+N('Cash Flow Statement'!C12))/((N('Cash Flow Statement'!C10)+N('Cash Flow Statement'!C11)+N('Cash Flow Statement'!C12))+'Balance Sheet'!C19)),"n/m") | D24: =IFERROR(((N('Cash Flow Statement'!C10)+N('Cash Flow Statement'!C11)+N('Cash Flow Statement'!C12))/((N('Cash Flow Statement'!C10)+N('Cash Flow Statement'!C11)+N('Cash Flow Statement'!C12))+'Balance Sheet'!C19))/((N('Cash Flow Statement'!D10)+N('Cash Flow Statement'!D11)+N('Cash Flow Statement'!D12))/((N('Cash Flow Statement'!D10)+N('Cash Flow Statement'!D11)+N('Cash Flow Statement'!D12))+'Balance Sheet'!D19)),"n/m") | E24: =IFERROR(((N('Cash Flow Statement'!D10)+N('Cash Flow Statement'!D11)+N('Cash Flow Statement'!D12))/((N('Cash Flow Statement'!D10)+N('Cash Flow Statement'!D11)+N('Cash Flow Statement'!D12))+'Balance Sheet'!D19))/((N('Cash Flow Statement'!E10)+N('Cash Flow Statement'!E11)+N('Cash Flow Statement'!E12))/((N('Cash Flow Statement'!E10)+N('Cash Flow Statement'!E11)+N('Cash Flow Statement'!E12))+'Balance Sheet'!E19)),"n/m") | F24: =IFERROR(((N('Cash Flow Statement'!E10)+N('Cash Flow Statement'!E11)+N('Cash Flow Statement'!E12))/((N('Cash Flow Statement'!E10)+N('Cash Flow Statement'!E11)+N('Cash Flow Statement'!E12))+'Balance Sheet'!E19))/((N('Cash Flow Statement'!F10)+N('Cash Flow Statement'!F11)+N('Cash Flow Statement'!F12))/((N('Cash Flow Statement'!F10)+N('Cash Flow Statement'!F11)+N('Cash Flow Statement'!F12))+'Balance Sheet'!F19)),"n/m") | G24: =IFERROR(((N('Cash Flow Statement'!F10)+N('Cash Flow Statement'!F11)+N('Cash Flow Statement'!F12))/((N('Cash Flow Statement'!F10)+N('Cash Flow Statement'!F11)+N('Cash Flow Statement'!F12))+'Balance Sheet'!F19))/((N('Cash Flow Statement'!G10)+N('Cash Flow Statement'!G11)+N('Cash Flow Statement'!G12))/((N('Cash Flow Statement'!G10)+N('Cash Flow Statement'!G11)+N('Cash Flow Statement'!G12))+'Balance Sheet'!G19)),"n/m") | H24: =IFERROR(((N('Cash Flow Statement'!G10)+N('Cash Flow Statement'!G11)+N('Cash Flow Statement'!G12))/((N('Cash Flow Statement'!G10)+N('Cash Flow Statement'!G11)+N('Cash Flow Statement'!G12))+'Balance Sheet'!G19))/((N('Cash Flow Statement'!H10)+N('Cash Flow Statement'!H11)+N('Cash Flow Statement'!H12))/((N('Cash Flow Statement'!H10)+N('Cash Flow Statement'!H11)+N('Cash Flow Statement'!H12))+'Balance Sheet'!H19)),"n/m") | I24: =IFERROR(((N('Cash Flow Statement'!H10)+N('Cash Flow Statement'!H11)+N('Cash Flow Statement'!H12))/((N('Cash Flow Statement'!H10)+N('Cash Flow Statement'!H11)+N('Cash Flow Statement'!H12))+'Balance Sheet'!H19))/((N('Cash Flow Statement'!I10)+N('Cash Flow Statement'!I11)+N('Cash Flow Statement'!I12))/((N('Cash Flow Statement'!I10)+N('Cash Flow Statement'!I11)+N('Cash Flow Statement'!I12))+'Balance Sheet'!I19)),"n/m") | J24: =IFERROR(((N('Cash Flow Statement'!I10)+N('Cash Flow Statement'!I11)+N('Cash Flow Statement'!I12))/((N('Cash Flow Statement'!I10)+N('Cash Flow Statement'!I11)+N('Cash Flow Statement'!I12))+'Balance Sheet'!I19))/((N('Cash Flow Statement'!J10)+N('Cash Flow Statement'!J11)+N('Cash Flow Statement'!J12))/((N('Cash Flow Statement'!J10)+N('Cash Flow Statement'!J11)+N('Cash Flow Statement'!J12))+'Balance Sheet'!J19)),"n/m") | K24: =IFERROR(((N('Cash Flow Statement'!J10)+N('Cash Flow Statement'!J11)+N('Cash Flow Statement'!J12))/((N('Cash Flow Statement'!J10)+N('Cash Flow Statement'!J11)+N('Cash Flow Statement'!J12))+'Balance Sheet'!J19))/((N('Cash Flow Statement'!K10)+N('Cash Flow Statement'!K11)+N('Cash Flow Statement'!K12))/((N('Cash Flow Statement'!K10)+N('Cash Flow Statement'!K11)+N('Cash Flow Statement'!K12))+'Balance Sheet'!K19)),"n/m") | L24: DEPI sums the CF D&A lines present each year (2016-2020: dep+impairment of P&E plus amortization+impairment of intangibles; 2021+: depreciation of P&E only - as-filed granularity change); AQI uses 1-(CA+PPE)/TA (securities not separable)
A25: SGAI (SG&A index; S&M+G&A) | B25: n/a | C25: =IFERROR(((ABS('Income Statement'!C11)+ABS('Income Statement'!C12))/'Income Statement'!C7)/((ABS('Income Statement'!B11)+ABS('Income Statement'!B12))/'Income Statement'!B7),"n/m") | D25: =IFERROR(((ABS('Income Statement'!D11)+ABS('Income Statement'!D12))/'Income Statement'!D7)/((ABS('Income Statement'!C11)+ABS('Income Statement'!C12))/'Income Statement'!C7),"n/m") | E25: =IFERROR(((ABS('Income Statement'!E11)+ABS('Income Statement'!E12))/'Income Statement'!E7)/((ABS('Income Statement'!D11)+ABS('Income Statement'!D12))/'Income Statement'!D7),"n/m") | F25: =IFERROR(((ABS('Income Statement'!F11)+ABS('Income Statement'!F12))/'Income Statement'!F7)/((ABS('Income Statement'!E11)+ABS('Income Statement'!E12))/'Income Statement'!E7),"n/m") | G25: =IFERROR(((ABS('Income Statement'!G11)+ABS('Income Statement'!G12))/'Income Statement'!G7)/((ABS('Income Statement'!F11)+ABS('Income Statement'!F12))/'Income Statement'!F7),"n/m") | H25: =IFERROR(((ABS('Income Statement'!H11)+ABS('Income Statement'!H12))/'Income Statement'!H7)/((ABS('Income Statement'!G11)+ABS('Income Statement'!G12))/'Income Statement'!G7),"n/m") | I25: =IFERROR(((ABS('Income Statement'!I11)+ABS('Income Statement'!I12))/'Income Statement'!I7)/((ABS('Income Statement'!H11)+ABS('Income Statement'!H12))/'Income Statement'!H7),"n/m") | J25: =IFERROR(((ABS('Income Statement'!J11)+ABS('Income Statement'!J12))/'Income Statement'!J7)/((ABS('Income Statement'!I11)+ABS('Income Statement'!I12))/'Income Statement'!I7),"n/m") | K25: =IFERROR(((ABS('Income Statement'!K11)+ABS('Income Statement'!K12))/'Income Statement'!K7)/((ABS('Income Statement'!J11)+ABS('Income Statement'!J12))/'Income Statement'!J7),"n/m")
A26: LVGI (leverage index) | B26: n/a | C26: =IFERROR((('Balance Sheet'!C33+'Balance Sheet'!C36)/'Balance Sheet'!C24)/(('Balance Sheet'!B33+'Balance Sheet'!B36)/'Balance Sheet'!B24),"n/m") | D26: =IFERROR((('Balance Sheet'!D33+'Balance Sheet'!D36)/'Balance Sheet'!D24)/(('Balance Sheet'!C33+'Balance Sheet'!C36)/'Balance Sheet'!C24),"n/m") | E26: =IFERROR((('Balance Sheet'!E33+'Balance Sheet'!E36)/'Balance Sheet'!E24)/(('Balance Sheet'!D33+'Balance Sheet'!D36)/'Balance Sheet'!D24),"n/m") | F26: =IFERROR((('Balance Sheet'!F33+'Balance Sheet'!F36)/'Balance Sheet'!F24)/(('Balance Sheet'!E33+'Balance Sheet'!E36)/'Balance Sheet'!E24),"n/m") | G26: =IFERROR((('Balance Sheet'!G33+'Balance Sheet'!G36)/'Balance Sheet'!G24)/(('Balance Sheet'!F33+'Balance Sheet'!F36)/'Balance Sheet'!F24),"n/m") | H26: =IFERROR((('Balance Sheet'!H33+'Balance Sheet'!H36)/'Balance Sheet'!H24)/(('Balance Sheet'!G33+'Balance Sheet'!G36)/'Balance Sheet'!G24),"n/m") | I26: =IFERROR((('Balance Sheet'!I33+'Balance Sheet'!I36)/'Balance Sheet'!I24)/(('Balance Sheet'!H33+'Balance Sheet'!H36)/'Balance Sheet'!H24),"n/m") | J26: =IFERROR((('Balance Sheet'!J33+'Balance Sheet'!J36)/'Balance Sheet'!J24)/(('Balance Sheet'!I33+'Balance Sheet'!I36)/'Balance Sheet'!I24),"n/m") | K26: =IFERROR((('Balance Sheet'!K33+'Balance Sheet'!K36)/'Balance Sheet'!K24)/(('Balance Sheet'!J33+'Balance Sheet'!J36)/'Balance Sheet'!J24),"n/m")
A27: TATA ((NI-CFO)/TA) | B27: n/a | C27: =(C13-C14)/'Balance Sheet'!C24 | D27: =(D13-D14)/'Balance Sheet'!D24 | E27: =(E13-E14)/'Balance Sheet'!E24 | F27: =(F13-F14)/'Balance Sheet'!F24 | G27: =(G13-G14)/'Balance Sheet'!G24 | H27: =(H13-H14)/'Balance Sheet'!H24 | I27: =(I13-I14)/'Balance Sheet'!I24 | J27: =(J13-J14)/'Balance Sheet'!J24 | K27: =(K13-K14)/'Balance Sheet'!K24
A28: M-SCORE | B28: n/a | C28: =IFERROR(-4.84+0.92*C20+0.528*C21+0.404*C22+0.892*C23+0.115*C24-0.172*C25+4.679*C27-0.327*C26,"n/m") | D28: =IFERROR(-4.84+0.92*D20+0.528*D21+0.404*D22+0.892*D23+0.115*D24-0.172*D25+4.679*D27-0.327*D26,"n/m") | E28: =IFERROR(-4.84+0.92*E20+0.528*E21+0.404*E22+0.892*E23+0.115*E24-0.172*E25+4.679*E27-0.327*E26,"n/m") | F28: =IFERROR(-4.84+0.92*F20+0.528*F21+0.404*F22+0.892*F23+0.115*F24-0.172*F25+4.679*F27-0.327*F26,"n/m") | G28: =IFERROR(-4.84+0.92*G20+0.528*G21+0.404*G22+0.892*G23+0.115*G24-0.172*G25+4.679*G27-0.327*G26,"n/m") | H28: =IFERROR(-4.84+0.92*H20+0.528*H21+0.404*H22+0.892*H23+0.115*H24-0.172*H25+4.679*H27-0.327*H26,"n/m") | I28: =IFERROR(-4.84+0.92*I20+0.528*I21+0.404*I22+0.892*I23+0.115*I24-0.172*I25+4.679*I27-0.327*I26,"n/m") | J28: =IFERROR(-4.84+0.92*J20+0.528*J21+0.404*J22+0.892*J23+0.115*J24-0.172*J25+4.679*J27-0.327*J26,"n/m") | K28: =IFERROR(-4.84+0.92*K20+0.528*K21+0.404*K22+0.892*K23+0.115*K24-0.172*K25+4.679*K27-0.327*K26,"n/m")
A29: Verdict (> -1.78 flag; > -2.22 grey) | B29: n/a | C29: =IF(NOT(ISNUMBER(C28)),"n/m",IF(C28>-1.78,"FLAG",IF(C28>-2.22,"grey","ok"))) | D29: =IF(NOT(ISNUMBER(D28)),"n/m",IF(D28>-1.78,"FLAG",IF(D28>-2.22,"grey","ok"))) | E29: =IF(NOT(ISNUMBER(E28)),"n/m",IF(E28>-1.78,"FLAG",IF(E28>-2.22,"grey","ok"))) | F29: =IF(NOT(ISNUMBER(F28)),"n/m",IF(F28>-1.78,"FLAG",IF(F28>-2.22,"grey","ok"))) | G29: =IF(NOT(ISNUMBER(G28)),"n/m",IF(G28>-1.78,"FLAG",IF(G28>-2.22,"grey","ok"))) | H29: =IF(NOT(ISNUMBER(H28)),"n/m",IF(H28>-1.78,"FLAG",IF(H28>-2.22,"grey","ok"))) | I29: =IF(NOT(ISNUMBER(I28)),"n/m",IF(I28>-1.78,"FLAG",IF(I28>-2.22,"grey","ok"))) | J29: =IF(NOT(ISNUMBER(J28)),"n/m",IF(J28>-1.78,"FLAG",IF(J28>-2.22,"grey","ok"))) | K29: =IF(NOT(ISNUMBER(K28)),"n/m",IF(K28>-1.78,"FLAG",IF(K28>-2.22,"grey","ok"))) | L29: Beneish was fit on profitable-firm manipulators; the 2021/2023 server-life extensions move DEPI by construction (estimate changes, see disclosure-only memo in the Core Earnings Bridge)
A31: C. PIOTROSKI F-SCORE (9 signals)
A32: 1. ROA > 0 | B32: n/a | C32: =IF(('Income Statement'!C19/(('Balance Sheet'!C24+'Balance Sheet'!B24)/2))>0,1,0) | D32: =IF(('Income Statement'!D19/(('Balance Sheet'!D24+'Balance Sheet'!C24)/2))>0,1,0) | E32: =IF(('Income Statement'!E19/(('Balance Sheet'!E24+'Balance Sheet'!D24)/2))>0,1,0) | F32: =IF(('Income Statement'!F19/(('Balance Sheet'!F24+'Balance Sheet'!E24)/2))>0,1,0) | G32: =IF(('Income Statement'!G19/(('Balance Sheet'!G24+'Balance Sheet'!F24)/2))>0,1,0) | H32: =IF(('Income Statement'!H19/(('Balance Sheet'!H24+'Balance Sheet'!G24)/2))>0,1,0) | I32: =IF(('Income Statement'!I19/(('Balance Sheet'!I24+'Balance Sheet'!H24)/2))>0,1,0) | J32: =IF(('Income Statement'!J19/(('Balance Sheet'!J24+'Balance Sheet'!I24)/2))>0,1,0) | K32: =IF(('Income Statement'!K19/(('Balance Sheet'!K24+'Balance Sheet'!J24)/2))>0,1,0)
A33: 2. CFO > 0 | B33: n/a | C33: =IF('Cash Flow Statement'!C26>0,1,0) | D33: =IF('Cash Flow Statement'!D26>0,1,0) | E33: =IF('Cash Flow Statement'!E26>0,1,0) | F33: =IF('Cash Flow Statement'!F26>0,1,0) | G33: =IF('Cash Flow Statement'!G26>0,1,0) | H33: =IF('Cash Flow Statement'!H26>0,1,0) | I33: =IF('Cash Flow Statement'!I26>0,1,0) | J33: =IF('Cash Flow Statement'!J26>0,1,0) | K33: =IF('Cash Flow Statement'!K26>0,1,0)
A34: 3. dROA > 0 | B34: n/a | C34: n/a | D34: =IF(('Income Statement'!D19/(('Balance Sheet'!D24+'Balance Sheet'!C24)/2))>('Income Statement'!C19/(('Balance Sheet'!C24+'Balance Sheet'!B24)/2)),1,0) | E34: =IF(('Income Statement'!E19/(('Balance Sheet'!E24+'Balance Sheet'!D24)/2))>('Income Statement'!D19/(('Balance Sheet'!D24+'Balance Sheet'!C24)/2)),1,0) | F34: =IF(('Income Statement'!F19/(('Balance Sheet'!F24+'Balance Sheet'!E24)/2))>('Income Statement'!E19/(('Balance Sheet'!E24+'Balance Sheet'!D24)/2)),1,0) | G34: =IF(('Income Statement'!G19/(('Balance Sheet'!G24+'Balance Sheet'!F24)/2))>('Income Statement'!F19/(('Balance Sheet'!F24+'Balance Sheet'!E24)/2)),1,0) | H34: =IF(('Income Statement'!H19/(('Balance Sheet'!H24+'Balance Sheet'!G24)/2))>('Income Statement'!G19/(('Balance Sheet'!G24+'Balance Sheet'!F24)/2)),1,0) | I34: =IF(('Income Statement'!I19/(('Balance Sheet'!I24+'Balance Sheet'!H24)/2))>('Income Statement'!H19/(('Balance Sheet'!H24+'Balance Sheet'!G24)/2)),1,0) | J34: =IF(('Income Statement'!J19/(('Balance Sheet'!J24+'Balance Sheet'!I24)/2))>('Income Statement'!I19/(('Balance Sheet'!I24+'Balance Sheet'!H24)/2)),1,0) | K34: =IF(('Income Statement'!K19/(('Balance Sheet'!K24+'Balance Sheet'!J24)/2))>('Income Statement'!J19/(('Balance Sheet'!J24+'Balance Sheet'!I24)/2)),1,0)
A35: 4. CFO > NI (accruals) | B35: n/a | C35: =IF('Cash Flow Statement'!C26>'Income Statement'!C19,1,0) | D35: =IF('Cash Flow Statement'!D26>'Income Statement'!D19,1,0) | E35: =IF('Cash Flow Statement'!E26>'Income Statement'!E19,1,0) | F35: =IF('Cash Flow Statement'!F26>'Income Statement'!F19,1,0) | G35: =IF('Cash Flow Statement'!G26>'Income Statement'!G19,1,0) | H35: =IF('Cash Flow Statement'!H26>'Income Statement'!H19,1,0) | I35: =IF('Cash Flow Statement'!I26>'Income Statement'!I19,1,0) | J35: =IF('Cash Flow Statement'!J26>'Income Statement'!J19,1,0) | K35: =IF('Cash Flow Statement'!K26>'Income Statement'!K19,1,0)
